Workbook

Sheet 使い方
A1: ■ このファイルの使い方（Excelだけで完結します。マクロもPythonも使いません）
A3: 1.「入力」シートに、名列順で生徒の情報を入力します（黄色いセル）。
A4: ・学科は6種類からドロップダウンで選べます（空欄なら「設定」の既定の学科）。
A5: ・郵便番号を入れると、ふりがな（住所）が自動で入ります（大阪府・和歌山県・奈良県）。
A6: 連絡先のふりがなも、連絡先の郵便番号から同じように入ります。
A7: 読みを直したいときは、そのセルに上から書き込んでください（そのセルだけ自動が外れます）。
A8: 郵便番号では町名までしか分からないので、番地の読みが要るときは書き足してください。
A9: ・連絡先を空欄にすると、履歴書には自動で「同上」と入ります。
A10: ・生年月日は「2008/5/12」のように日付で入力してください（元号と満○歳は自動）。
A12: 2.「履歴書」シートが、そのまま印刷する用紙です（1人＝1ページ・上から入力シートのNo順）。
A13: 画面をスクロールすれば、印刷前に全員分を確認できます。
A15: 3. 印刷・PDFにする（No.○ から No.○ まで）
... A55: ・非表示のシートは変えないでください。

Sheet 入力
A1: 入力（1行＝1生徒・名列順） | D1: 黄色いセルに入力すると、「履歴書」シートに自動で反映されます（1人＝1ページ・Noの順）。印刷は「設定」シートで No.○ 〜 No.○ を指定してください。
A2: 生徒 | G2: 現住所 | J2: 在籍校 | K2: 連絡先 | N2: 資格等 | Z2: 校内外の諸活動 | AA2: 志望の動機など | AD2: 職歴 | AH2: 備考
A3: No | B3: 組 | C3: 出席番号 | D3: 氏名 | E3: ふりがな（氏名） | F3: 生年月日 | G3: 郵便番号 | H3: 住所 | I3: ふりがな（住所） | J3: 学科 | K3: 連絡先 郵便番号 | L3: 連絡先 住所 | M3: 連絡先 ふりがな | N3: 資格1 名称 | O3: 資格1 取得年月 | P3: 資格2 名称 | Q3: 資格2 取得年月 | R3: 資格3 名称 | S3: 資格3 取得年月 | T3: 資格4 名称 | U3: 資格4 取得年月 | V3: 資格5 名称 | W3: 資格5 取得年月 | X3: 資格6 名称 | Y3: 資格6 取得年月 | Z3: 校内外の諸活動 | AA3: 志望の動機 | AB3: 希望の職種 | AC3: アピールポイント | AD3: 職歴1 年月 | AE3: 職歴1 内容 | AF3: 職歴2 年月 | AG3: 職歴2 内容 | AH3: 備考 | AJ3: 照合用（自動）
A4: meta.no | B4: meta.class | C4: meta.number | D4: name | E4: name_kana | F4: birth | G4: zip | H4: address | I4: address_kana | J4: course | K4: contact_zip | L4: contact_address | M4: contact_kana | N4: license.1.name | O4: license.1.ym | P4: license.2.name | Q4: license.2.ym | R4: license.3.name | S4: license.3.ym | T4: license.4.name | U4: license.4.ym | V4: license.5.name | W4: license.5.ym | X4: license.6.name | Y4: license.6.ym | Z4: activities | AA4: motivation | AB4: desired_job | AC4: appeal | AD4: job.1.ym | AE4: job.1.text | AF4: job.2.ym | AG4: job.2.text | AH4: remarks
A5: 1 | B5: 3年2組 | C5: 1 | D5: 佐野 太郎 | E5: さの たろう | F5: 39580 | G5: 5980001 | H5: 大阪府泉佐野市市場東1丁目2-3 サンプルハイツ101 | I5: =IF(G5="","",IFERROR(VLOOKUP(TEXT(VALUE(SUBSTITUTE(G5,"-","")),"0000000"),郵便番号!$A:$C,3,FALSE),"")) | J5: 機械系機械技術科（専科） | M5: =IF(K5="","",IFERROR(VLOOKUP(TEXT(VALUE(SUBSTITUTE(K5,"-","")),"0000000"),郵便番号!$A:$C,3,FALSE),"")) | N5: 電気工事士第二種 | O5: 45444 | P5: 危険物取扱者乙4 | Q5: 45717 | R5: 技能検定 機械加工（普通旋盤作業）3級 | S5: 45962 | Z5: ・1年〜3年 機械研究部に所属（3年次は副部長） ・2年 ものづくりコンテスト旋盤作業部門 校内代表 ・3年 体育大会 応援団リーダー | AA5: 実習で金属を削って形にする面白さを知り、ものづくりの現場で働きたいと考えるようになりました。貴社は多品種少量の精密加工に強みがあり、若いうちから幅広い機械に触れられると伺っています。学校で学んだ機械加工の基礎を早く現場で活かし、確かな技術を身につけて長く貢献したいと思い志望しました。 | AB5: 機械加工・生産技術 | AC5: 旋盤とフライス盤の実習で、寸法公差を守る段取りと確認を身につけました。分からないことはその場で質問し、最後まで丁寧にやり切ることを大切にしています。 | AH5: 普通自動車免許は卒業後に取得予定です。 | AJ5: =SUBSTITUTE(SUBSTITUTE(D5," ","")," ","")
A6: 2 | B6: 3年2組 | C6: 2 | D6: 近畿 花子 | E6: きんき はなこ | F6: 39755 | G6: 5900001 | H6: 大阪府堺市堺区南瓦町3-1 テストレジデンス2201号室 | I6: =IF(G6="","",IFERROR(VLOOKUP(TEXT(VALUE(SUBSTITUTE(G6,"-","")),"0000000"),郵便番号!$A:$C,3,FALSE),"")) | J6: 産業創造系製品開発科（専科） | K6: 5980048 | L6: 大阪府泉佐野市りんくう往来北1-1 保護者 近畿一郎方 | M6: =IF(K6="","",IFERROR(VLOOKUP(TEXT(VALUE(SUBSTITUTE(K6,"-","")),"0000000"),郵便番号!$A:$C,3,FALSE),"")) | N6: 計算技術検定3級 | O6: 45597 | P6: 基礎製図検定 | Q6: 45413 | Z6: ・生徒会 会計（2年） ・吹奏楽部 パートリーダー（3年） ・海岸清掃活動に参加（1年〜3年） | AA6: 工場見学で、たくさんの部品が計画どおりに動いて製品になる仕組みに興味を持ちました。簿記と情報の授業で学んだことを活かして、現場を支える仕事に就きたいと考え志望しました。 | AB6: 生産管理・事務 | AC6: 3年間、無遅刻無欠席で続けてきました。人と話すことが好きで、部活動では初心者の後輩の指導を担当しました。 | AJ6: =SUBSTITUTE(SUBSTITUTE(D6," ","")," ","")
A7: 3 | B7: 3年2組 | C7: 3 | D7: 泉州 一郎 | E7: せんしゅう いちろう | F7: 39467 | G7: 5960076 | H7: 大阪府岸和田市野田町1-1-1 | I7: =IF(G7="","",IFERROR(VLOOKUP(TEXT(VALUE(SUBSTITUTE(G7,"-","")),"0000000"),郵便番号!$A:$C,3,FALSE),"")) | J7: 電気系電気技術科（専科） | M7: =IF(K7="","",IFERROR(VLOOKUP(TEXT(VALUE(SUBSTITUTE(K7,"-","")),"0000000"),郵便番号!$A:$C,3,FALSE),"")) | N7: 小型フォークリフト運転特別教育講習修了 | O7: 45870 | Z7: ・ソフトテニス部 主将（3年） ・泉州オープンファクトリー参加（2年） | AA7: インターンシップで貴社の現場を見学し、機械を扱う正確さに憧れました。基礎から学んで一人前になりたいと思い志望しました。 | AB7: 機械オペレーター | AC7: 部活動で主将を務め、練習メニューを考えて部員をまとめました。体力に自信があります。 | AJ7: =SUBSTITUTE(SUBSTITUTE(D7," ","")," ","")
A8: 4 | I8: =IF(G8="","",IFERROR(VLOOKUP(TEXT(VALUE(SUBSTITUTE(G8,"-","")),"0000000"),郵便番号!$A:$C,3,FALSE),"")) | M8: =IF(K8="","",IFERROR(VLOOKUP(TEXT(VALUE(SUBSTITUTE(K8,"-","")),"0000000"),郵便番号!$A:$C,3,FALSE),"")) | AJ8: =SUBSTITUTE(SUBSTITUTE(D8," ","")," ","")
A9: 5 | I9: =IF(G9="","",IFERROR(VLOOKUP(TEXT(VALUE(SUBSTITUTE(G9,"-","")),"0000000"),郵便番号!$A:$C,3,FALSE),"")) | M9: =IF(K9="","",IFERROR(VLOOKUP(TEXT(VALUE(SUBSTITUTE(K9,"-","")),"0000000"),郵便番号!$A:$C,3,FALSE),"")) | AJ9: =SUBSTITUTE(SUBSTITUTE(D9," ","")," ","")
A10: 6 | I10: =IF(G10="","",IFERROR(VLOOKUP(TEXT(VALUE(SUBSTITUTE(G10,"-","")),"0000000"),郵便番号!$A:$C,3,FALSE),"")) | M10: =IF(K10="","",IFERROR(VLOOKUP(TEXT(VALUE(SUBSTITUTE(K10,"-","")),"0000000"),郵便番号!$A:$C,3,FALSE),"")) | AJ10: =SUBSTITUTE(SUBSTITUTE(D10," ","")," ","")
A11: 7 | I11: =IF(G11="","",IFERROR(VLOOKUP(TEXT(VALUE(SUBSTITUTE(G11,"-","")),"0000000"),郵便番号!$A:$C,3,FALSE),"")) | M11: =IF(K11="","",IFERROR(VLOOKUP(TEXT(VALUE(SUBSTITUTE(K11,"-","")),"0000000"),郵便番号!$A:$C,3,FALSE),"")) | AJ11: =SUBSTITUTE(SUBSTITUTE(D11," ","")," ","")
A12: 8 | I12: =IF(G12="","",IFERROR(VLOOKUP(TEXT(VALUE(SUBSTITUTE(G12,"-","")),"0000000"),郵便番号!$A:$C,3,FALSE),"")) | M12: =IF(K12="","",IFERROR(VLOOKUP(TEXT(VALUE(SUBSTITUTE(K12,"-","")),"0000000"),郵便番号!$A:$C,3,FALSE),"")) | AJ12: =SUBSTITUTE(SUBSTITUTE(D12," ","")," ","")
A13: 9 | I13: =IF(G13="","",IFERROR(VLOOKUP(TEXT(VALUE(SUBSTITUTE(G13,"-","")),"0000000"),郵便番号!$A:$C,3,FALSE),"")) | M13: =IF(K13="","",IFERROR(VLOOKUP(TEXT(VALUE(SUBSTITUTE(K13,"-","")),"0000000"),郵便番号!$A:$C,3,FALSE),"")) | AJ13: =SUBSTITUTE(SUBSTITUTE(D13," ","")," ","")
A14: 10 | I14: =IF(G14="","",IFERROR(VLOOKUP(TEXT(VALUE(SUBSTITUTE(G14,"-","")),"0000000"),郵便番号!$A:$C,3,FALSE),"")) | M14: =IF(K14="","",IFERROR(VLOOKUP(TEXT(VALUE(SUBSTITUTE(K14,"-","")),"0000000"),郵便番号!$A:$C,3,FALSE),"")) | AJ14: =SUBSTITUTE(SUBSTITUTE(D14," ","")," ","")
A15: 11 | I15: =IF(G15="","",IFERROR(VLOOKUP(TEXT(VALUE(SUBSTITUTE(G15,"-","")),"0000000"),郵便番号!$A:$C,3,FALSE),"")) | M15: =IF(K15="","",IFERROR(VLOOKUP(TEXT(VALUE(SUBSTITUTE(K15,"-","")),"0000000"),郵便番号!$A:$C,3,FALSE),"")) | AJ15: =SUBSTITUTE(SUBSTITUTE(D15," ","")," ","")
A16: 12 | I16: =IF(G16="","",IFERROR(VLOOKUP(TEXT(VALUE(SUBSTITUTE(G16,"-","")),"0000000"),郵便番号!$A:$C,3,FALSE),"")) | M16: =IF(K16="","",IFERROR(VLOOKUP(TEXT(VALUE(SUBSTITUTE(K16,"-","")),"0000000"),郵便番号!$A:$C,3,FALSE),"")) | AJ16: =SUBSTITUTE(SUBSTITUTE(D16," ","")," ","")
A17: 13 | I17: =IF(G17="","",IFERROR(VLOOKUP(TEXT(VALUE(SUBSTITUTE(G17,"-","")),"0000000"),郵便番号!$A:$C,3,FALSE),"")) | M17: =IF(K17="","",IFERROR(VLOOKUP(TEXT(VALUE(SUBSTITUTE(K17,"-","")),"0000000"),郵便番号!$A:$C,3,FALSE),"")) | AJ17: =SUBSTITUTE(SUBSTITUTE(D17," ","")," ","")
A18: 14 | I18: =IF(G18="","",IFERROR(VLOOKUP(TEXT(VALUE(SUBSTITUTE(G18,"-","")),"0000000"),郵便番号!$A:$C,3,FALSE),"")) | M18: =IF(K18="","",IFERROR(VLOOKUP(TEXT(VALUE(SUBSTITUTE(K18,"-","")),"0000000"),郵便番号!$A:$C,3,FALSE),"")) | AJ18: =SUBSTITUTE(SUBSTITUTE(D18," ","")," ","")
A19: 15 | I19: =IF(G19="","",IFERROR(VLOOKUP(TEXT(VALUE(SUBSTITUTE(G19,"-","")),"0000000"),郵便番号!$A:$C,3,FALSE),"")) | M19: =IF(K19="","",IFERROR(VLOOKUP(TEXT(VALUE(SUBSTITUTE(K19,"-","")),"0000000"),郵便番号!$A:$C,3,FALSE),"")) | AJ19: =SUBSTITUTE(SUBSTITUTE(D19," ","")," ","")
... A44: 40 | I44: =IF(G44="","",IFERROR(VLOOKUP(TEXT(VALUE(SUBSTITUTE(G44,"-","")),"0000000"),郵便番号!$A:$C,3,FALSE),"")) | M44: =IF(K44="","",IFERROR(VLOOKUP(TEXT(VALUE(SUBSTITUTE(K44,"-","")),"0000000"),郵便番号!$A:$C,3,FALSE),"")) | AJ44: =SUBSTITUTE(SUBSTITUTE(D44," ","")," ","")

Sheet 資格取込
A1: 資格取込（1行＝1件で貼り付けてください）
A2: A6 以降に、資格取得の一覧をそのまま貼り付けます。「入力」シートの名簿と照合して、各生徒の資格欄に自動で追加します。
A3: 書式: 3-2-15〔空白またはタブ〕山田 太郎 基礎製図検定 令和6年7月10日 …学年-組-出席番号 → 氏名 → 資格名 → 取得日 の順。
A4: 先頭の番号がないときは氏名で照合します。取得日は 令和6年7月10日 / 2024/7/10 のどちらでも。すでに「入力」シートに手入力してある資格と同じものは「重複」として飛ばします。
A5: 貼付原文 | B5: 整形 | C5: 語数 | D5: 語1 | E5: 語2 | F5: 語3 | G5: 語4 | H5: 語5 | I5: 語6 | J5: 語7 | K5: 語8 | L5: ID | M5: ID有 | N5: 組 | O5: 出席番号 | P5: 氏名 | Q5: 資格名（貼付） | R5: 正式名称 | S5: 取得日 | T5: 名簿No | U5: 名簿の氏名 | V5: 状態 | W5: 有効 | X5: 行 | Y5: 順位 | Z5: キー
A6: 3-2-1 佐野 太郎 計算技術検定3級 令和6年11月15日 | B6: =TRIM(SUBSTITUTE(SUBSTITUTE(SUBSTITUTE(A6,CHAR(9)," ")," "," "),CHAR(160)," ")) | C6: =IF(B6="",0,LEN(B6)-LEN(SUBSTITUTE(B6," ",""))+1) | D6: =IF(C6>=1,TRIM(MID(SUBSTITUTE(B6," ",REPT(" ",200)),1,200)),"") | E6: =IF(C6>=2,TRIM(MID(SUBSTITUTE(B6," ",REPT(" ",200)),201,200)),"") | F6: =IF(C6>=3,TRIM(MID(SUBSTITUTE(B6," ",REPT(" ",200)),401,200)),"") | G6: =IF(C6>=4,TRIM(MID(SUBSTITUTE(B6," ",REPT(" ",200)),601,200)),"") | H6: =IF(C6>=5,TRIM(MID(SUBSTITUTE(B6," ",REPT(" ",200)),801,200)),"") | I6: =IF(C6>=6,TRIM(MID(SUBSTITUTE(B6," ",REPT(" ",200)),1001,200)),"") | J6: =IF(C6>=7,TRIM(MID(SUBSTITUTE(B6," ",REPT(" ",200)),1201,200)),"") | K6: =IF(C6>=8,TRIM(MID(SUBSTITUTE(B6," ",REPT(" ",200)),1401,200)),"") | L6: =SUBSTITUTE(SUBSTITUTE(SUBSTITUTE(D6,"年","-"),"組","-"),"番","") | M6: =IF(D6="",0,IF(ISNUMBER(VALUE(SUBSTITUTE(L6,"-",""))),1,0)) | N6: =IF(M6=0,"",IFERROR(VALUE(TRIM(MID(SUBSTITUTE(L6,"-",REPT(" ",100)),101,100))),"")) | O6: =IF(M6=0,"",IFERROR(VALUE(TRIM(RIGHT(SUBSTITUTE(L6,"-",REPT(" ",100)),100))),"")) | P6: =IF(B6="","",TRIM(INDEX($D6:$K6,IF(M6=1,2,1))&IF(AD6>=2," "&INDEX($D6:$K6,IF(M6=1,2,1)+1),"")&IF(AD6>=3," "&INDEX($D6:$K6,IF(M6=1,2,1)+2),""))) | Q6: =IF(C6<2,"",TRIM(IF(AND(2>=(IF(M6=1,2,1)+AD6),2<=C6-IF(S6="",0,1)),E6&" ","")&IF(AND(3>=(IF(M6=1,2,1)+AD6),3<=C6-IF(S6="",0,1)),F6&" ","")&IF(AND(4>=(IF(M6=1,2,1)+AD6),4<=C6-IF(S6="",0,1)),G6&" ","")&IF(AND(5>=(IF(M6=1,2,1)+AD6),5<=C6-IF(S6="",0,1)),H6&" ","")&IF(AND(6>=(IF(M6=1,2,1)+AD6),6<=C6-IF(S6="",0,1)),I6&" ","")&IF(AND(7>=(IF(M6=1,2,1)+AD6),7<=C6-IF(S6="",0,1)),J6&" ","")&IF(AND(8>=(IF(M6=1,2,1)+AD6),8<=C6-IF(S6="",0,1)),K6&" ",""))) | R6: =IF(Q6="","",IFERROR(INDEX(資格マスタ!$B:$B,MATCH(ASC(SUBSTITUTE(SUBSTITUTE(Q6," ","")," ","")),資格マスタ!$D:$D,0)),Q6)) | S6: =IF(C6<2,"",IFERROR(IF(OR(LEFT(INDEX(D6:K6,MIN(8,MAX(1,C6))),2)="令和",LEFT(INDEX(D6:K6,MIN(8,MAX(1,C6))),2)="平成",LEFT(INDEX(D6:K6,MIN(8,MAX(1,C6))),2)="昭和"),DATE(VALUE(MID(INDEX(D6:K6,MIN(8,MAX(1,C6))),3,FIND("年",INDEX(D6:K6,MIN(8,MAX(1,C6))))-3))+IF(LEFT(INDEX(D6:K6,MIN(8,MAX(1,C6))),2)="令和",2018,IF(LEFT(INDEX(D6:K6,MIN(8,MAX(1,C6))),2)="平成",1988,1925)),VALUE(MID(INDEX(D6:K6,MIN(8,MAX(1,C6))),FIND("年",INDEX(D6:K6,MIN(8,MAX(1,C6))))+1,FIND("月",INDEX(D6:K6,MIN(8,MAX(1,C6))))-FIND("年",INDEX(D6:K6,MIN(8,MAX(1,C6))))-1)),VALUE(SUBSTITUTE(MID(INDEX(D6:K6,MIN(8,MAX(1,C6))),FIND("月",INDEX(D6:K6,MIN(8,MAX(1,C6))))+1,10),"日",""))),DATE(VALUE(TRIM(MID(SUBSTITUTE(AA6,"/",REPT(" ",50)),1,50))),VALUE(TRIM(MID(SUBSTITUTE(AA6,"/",REPT(" ",50)),51,50))),VALUE(TRIM(MID(SUBSTITUTE(AA6,"/",REPT(" ",50)),101,50))))),IFERROR(DATEVALUE(INDEX(D6:K6,MIN(8,MAX(1,C6)))),""))) | T6: =IF(B6="","",IF(AB6<>"",AB6,IFERROR(MATCH(SUBSTITUTE(SUBSTITUTE(P6," ","")," ",""),入力!$AJ$5:$AJ$44,0),""))) | U6: =IF(T6="","",INDEX(入力!$D$5:$D$44,T6)) | V6: =IF(B6="","",IF(T6="","要確認（名簿と照合できません）",IF(R6="","要確認（資格名がありません）",IF(S6="","要確認（取得日が読めません）",IF((IF(INDEX(入力!$N$5:$N$44,T6)=R6,1,0)+IF(INDEX(入力!$P$5:$P$44,T6)=R6,1,0)+IF(INDEX(入力!$R$5:$R$44,T6)=R6,1,0)+IF(INDEX(入力!$T$5:$T$44,T6)=R6,1,0)+IF(INDEX(入力!$V$5:$V$44,T6)=R6,1,0)+IF(INDEX(入力!$X$5:$X$44,T6)=R6,1,0))+(COUNTIFS($T$6:$T$205,T6,$R$6:$R$205,R6,$X$6:$X$205,"<"&X6))>0,"重複","反映"))))) | W6: =IF(V6="反映",1,0) | X6: 6 | Y6: =IF(W6=0,"",COUNTIFS($T$6:$T$205,T6,$W$6:$W$205,1,$S$6:$S$205,"<"&S6)+COUNTIFS($T$6:$T$205,T6,$W$6:$W$205,1,$S$6:$S$205,S6,$X$6:$X$205,"<"&X6)+1) | Z6: =IF(Y6="","",T6&"_"&Y6) | AA6: =SUBSTITUTE(SUBSTITUTE(SUBSTITUTE(SUBSTITUTE(SUBSTITUTE(INDEX(D6:K6,MIN(8,MAX(1,C6))),"年","/"),"月","/"),"日",""),"-","/"),".","/") | AB6: =IFERROR(MATCH(O6,入力!$C$5:$C$44,0),"") | AC6: =IF(AB6="","",INDEX(入力!$AJ$5:$AJ$44,AB6)) | AD6: =IF(INDEX($D6:$K6,IF(M6=1,2,1))=AC6,1,IF(INDEX($D6:$K6,IF(M6=1,2,1))&INDEX($D6:$K6,IF(M6=1,2,1)+1)=AC6,2,IF(INDEX($D6:$K6,IF(M6=1,2,1))&INDEX($D6:$K6,IF(M6=1,2,1)+1)&INDEX($D6:$K6,IF(M6=1,2,1)+2)=AC6,3,IF(AB6<>"",2,IF(ISNUMBER(MATCH(INDEX($D6:$K6,IF(M6=1,2,1)),入力!$AJ$5:$AJ$44,0)),1,IF(ISNUMBER(MATCH(INDEX($D6:$K6,IF(M6=1,2,1))&INDEX($D6:$K6,IF(M6=1,2,1)+1),入力!$AJ$5:$AJ$44,0)),2,IF(ISNUMBER(MATCH(INDEX($D6:$K6,IF(M6=1,2,1))&INDEX($D6:$K6,IF(M6=1,2,1)+1)&INDEX($D6:$K6,IF(M6=1,2,1)+2),入力!$AJ$5:$AJ$44,0)),3,2)))))))
A7: 3-2-2 近畿 花子 実用英語検定2級 2025/6/8 | B7: =TRIM(SUBSTITUTE(SUBSTITUTE(SUBSTITUTE(A7,CHAR(9)," ")," "," "),CHAR(160)," ")) | C7: =IF(B7="",0,LEN(B7)-LEN(SUBSTITUTE(B7," ",""))+1) | D7: =IF(C7>=1,TRIM(MID(SUBSTITUTE(B7," ",REPT(" ",200)),1,200)),"") | E7: =IF(C7>=2,TRIM(MID(SUBSTITUTE(B7," ",REPT(" ",200)),201,200)),"") | F7: =IF(C7>=3,TRIM(MID(SUBSTITUTE(B7," ",REPT(" ",200)),401,200)),"") | G7: =IF(C7>=4,TRIM(MID(SUBSTITUTE(B7," ",REPT(" ",200)),601,200)),"") | H7: =IF(C7>=5,TRIM(MID(SUBSTITUTE(B7," ",REPT(" ",200)),801,200)),"") | I7: =IF(C7>=6,TRIM(MID(SUBSTITUTE(B7," ",REPT(" ",200)),1001,200)),"") | J7: =IF(C7>=7,TRIM(MID(SUBSTITUTE(B7," ",REPT(" ",200)),1201,200)),"") | K7: =IF(C7>=8,TRIM(MID(SUBSTITUTE(B7," ",REPT(" ",200)),1401,200)),"") | L7: =SUBSTITUTE(SUBSTITUTE(SUBSTITUTE(D7,"年","-"),"組","-"),"番","") | M7: =IF(D7="",0,IF(ISNUMBER(VALUE(SUBSTITUTE(L7,"-",""))),1,0)) | N7: =IF(M7=0,"",IFERROR(VALUE(TRIM(MID(SUBSTITUTE(L7,"-",REPT(" ",100)),101,100))),"")) | O7: =IF(M7=0,"",IFERROR(VALUE(TRIM(RIGHT(SUBSTITUTE(L7,"-",REPT(" ",100)),100))),"")) | P7: =IF(B7="","",TRIM(INDEX($D7:$K7,IF(M7=1,2,1))&IF(AD7>=2," "&INDEX($D7:$K7,IF(M7=1,2,1)+1),"")&IF(AD7>=3," "&INDEX($D7:$K7,IF(M7=1,2,1)+2),""))) | Q7: =IF(C7<2,"",TRIM(IF(AND(2>=(IF(M7=1,2,1)+AD7),2<=C7-IF(S7="",0,1)),E7&" ","")&IF(AND(3>=(IF(M7=1,2,1)+AD7),3<=C7-IF(S7="",0,1)),F7&" ","")&IF(AND(4>=(IF(M7=1,2,1)+AD7),4<=C7-IF(S7="",0,1)),G7&" ","")&IF(AND(5>=(IF(M7=1,2,1)+AD7),5<=C7-IF(S7="",0,1)),H7&" ","")&IF(AND(6>=(IF(M7=1,2,1)+AD7),6<=C7-IF(S7="",0,1)),I7&" ","")&IF(AND(7>=(IF(M7=1,2,1)+AD7),7<=C7-IF(S7="",0,1)),J7&" ","")&IF(AND(8>=(IF(M7=1,2,1)+AD7),8<=C7-IF(S7="",0,1)),K7&" ",""))) | R7: =IF(Q7="","",IFERROR(INDEX(資格マスタ!$B:$B,MATCH(ASC(SUBSTITUTE(SUBSTITUTE(Q7," ","")," ","")),資格マスタ!$D:$D,0)),Q7)) | S7: =IF(C7<2,"",IFERROR(IF(OR(LEFT(INDEX(D7:K7,MIN(8,MAX(1,C7))),2)="令和",LEFT(INDEX(D7:K7,MIN(8,MAX(1,C7))),2)="平成",LEFT(INDEX(D7:K7,MIN(8,MAX(1,C7))),2)="昭和"),DATE(VALUE(MID(INDEX(D7:K7,MIN(8,MAX(1,C7))),3,FIND("年",INDEX(D7:K7,MIN(8,MAX(1,C7))))-3))+IF(LEFT(INDEX(D7:K7,MIN(8,MAX(1,C7))),2)="令和",2018,IF(LEFT(INDEX(D7:K7,MIN(8,MAX(1,C7))),2)="平成",1988,1925)),VALUE(MID(INDEX(D7:K7,MIN(8,MAX(1,C7))),FIND("年",INDEX(D7:K7,MIN(8,MAX(1,C7))))+1,FIND("月",INDEX(D7:K7,MIN(8,MAX(1,C7))))-FIND("年",INDEX(D7:K7,MIN(8,MAX(1,C7))))-1)),VALUE(SUBSTITUTE(MID(INDEX(D7:K7,MIN(8,MAX(1,C7))),FIND("月",INDEX(D7:K7,MIN(8,MAX(1,C7))))+1,10),"日",""))),DATE(VALUE(TRIM(MID(SUBSTITUTE(AA7,"/",REPT(" ",50)),1,50))),VALUE(TRIM(MID(SUBSTITUTE(AA7,"/",REPT(" ",50)),51,50))),VALUE(TRIM(MID(SUBSTITUTE(AA7,"/",REPT(" ",50)),101,50))))),IFERROR(DATEVALUE(INDEX(D7:K7,MIN(8,MAX(1,C7)))),""))) | T7: =IF(B7="","",IF(AB7<>"",AB7,IFERROR(MATCH(SUBSTITUTE(SUBSTITUTE(P7," ","")," ",""),入力!$AJ$5:$AJ$44,0),""))) | U7: =IF(T7="","",INDEX(入力!$D$5:$D$44,T7)) | V7: =IF(B7="","",IF(T7="","要確認（名簿と照合できません）",IF(R7="","要確認（資格名がありません）",IF(S7="","要確認（取得日が読めません）",IF((IF(INDEX(入力!$N$5:$N$44,T7)=R7,1,0)+IF(INDEX(入力!$P$5:$P$44,T7)=R7,1,0)+IF(INDEX(入力!$R$5:$R$44,T7)=R7,1,0)+IF(INDEX(入力!$T$5:$T$44,T7)=R7,1,0)+IF(INDEX(入力!$V$5:$V$44,T7)=R7,1,0)+IF(INDEX(入力!$X$5:$X$44,T7)=R7,1,0))+(COUNTIFS($T$6:$T$205,T7,$R$6:$R$205,R7,$X$6:$X$205,"<"&X7))>0,"重複","反映"))))) | W7: =IF(V7="反映",1,0) | X7: 7 | Y7: =IF(W7=0,"",COUNTIFS($T$6:$T$205,T7,$W$6:$W$205,1,$S$6:$S$205,"<"&S7)+COUNTIFS($T$6:$T$205,T7,$W$6:$W$205,1,$S$6:$S$205,S7,$X$6:$X$205,"<"&X7)+1) | Z7: =IF(Y7="","",T7&"_"&Y7) | AA7: =SUBSTITUTE(SUBSTITUTE(SUBSTITUTE(SUBSTITUTE(SUBSTITUTE(INDEX(D7:K7,MIN(8,MAX(1,C7))),"年","/"),"月","/"),"日",""),"-","/"),".","/") | AB7: =IFERROR(MATCH(O7,入力!$C$5:$C$44,0),"") | AC7: =IF(AB7="","",INDEX(入力!$AJ$5:$AJ$44,AB7)) | AD7: =IF(INDEX($D7:$K7,IF(M7=1,2,1))=AC7,1,IF(INDEX($D7:$K7,IF(M7=1,2,1))&INDEX($D7:$K7,IF(M7=1,2,1)+1)=AC7,2,IF(INDEX($D7:$K7,IF(M7=1,2,1))&INDEX($D7:$K7,IF(M7=1,2,1)+1)&INDEX($D7:$K7,IF(M7=1,2,1)+2)=AC7,3,IF(AB7<>"",2,IF(ISNUMBER(MATCH(INDEX($D7:$K7,IF(M7=1,2,1)),入力!$AJ$5:$AJ$44,0)),1,IF(ISNUMBER(MATCH(INDEX($D7:$K7,IF(M7=1,2,1))&INDEX($D7:$K7,IF(M7=1,2,1)+1),入力!$AJ$5:$AJ$44,0)),2,IF(ISNUMBER(MATCH(INDEX($D7:$K7,IF(M7=1,2,1))&INDEX($D7:$K7,IF(M7=1,2,1)+1)&INDEX($D7:$K7,IF(M7=1,2,1)+2),入力!$AJ$5:$AJ$44,0)),3,2)))))))
A8: 3-2-3 泉州 一郎 危険物取扱者乙4 令和7年3月14日 | B8: =TRIM(SUBSTITUTE(SUBSTITUTE(SUBSTITUTE(A8,CHAR(9)," ")," "," "),CHAR(160)," ")) | C8: =IF(B8="",0,LEN(B8)-LEN(SUBSTITUTE(B8," ",""))+1) | D8: =IF(C8>=1,TRIM(MID(SUBSTITUTE(B8," ",REPT(" ",200)),1,200)),"") | E8: =IF(C8>=2,TRIM(MID(SUBSTITUTE(B8," ",REPT(" ",200)),201,200)),"") | F8: =IF(C8>=3,TRIM(MID(SUBSTITUTE(B8," ",REPT(" ",200)),401,200)),"") | G8: =IF(C8>=4,TRIM(MID(SUBSTITUTE(B8," ",REPT(" ",200)),601,200)),"") | H8: =IF(C8>=5,TRIM(MID(SUBSTITUTE(B8," ",REPT(" ",200)),801,200)),"") | I8: =IF(C8>=6,TRIM(MID(SUBSTITUTE(B8," ",REPT(" ",200)),1001,200)),"") | J8: =IF(C8>=7,TRIM(MID(SUBSTITUTE(B8," ",REPT(" ",200)),1201,200)),"") | K8: =IF(C8>=8,TRIM(MID(SUBSTITUTE(B8," ",REPT(" ",200)),1401,200)),"") | L8: =SUBSTITUTE(SUBSTITUTE(SUBSTITUTE(D8,"年","-"),"組","-"),"番","") | M8: =IF(D8="",0,IF(ISNUMBER(VALUE(SUBSTITUTE(L8,"-",""))),1,0)) | N8: =IF(M8=0,"",IFERROR(VALUE(TRIM(MID(SUBSTITUTE(L8,"-",REPT(" ",100)),101,100))),"")) | O8: =IF(M8=0,"",IFERROR(VALUE(TRIM(RIGHT(SUBSTITUTE(L8,"-",REPT(" ",100)),100))),"")) | P8: =IF(B8="","",TRIM(INDEX($D8:$K8,IF(M8=1,2,1))&IF(AD8>=2," "&INDEX($D8:$K8,IF(M8=1,2,1)+1),"")&IF(AD8>=3," "&INDEX($D8:$K8,IF(M8=1,2,1)+2),""))) | Q8: =IF(C8<2,"",TRIM(IF(AND(2>=(IF(M8=1,2,1)+AD8),2<=C8-IF(S8="",0,1)),E8&" ","")&IF(AND(3>=(IF(M8=1,2,1)+AD8),3<=C8-IF(S8="",0,1)),F8&" ","")&IF(AND(4>=(IF(M8=1,2,1)+AD8),4<=C8-IF(S8="",0,1)),G8&" ","")&IF(AND(5>=(IF(M8=1,2,1)+AD8),5<=C8-IF(S8="",0,1)),H8&" ","")&IF(AND(6>=(IF(M8=1,2,1)+AD8),6<=C8-IF(S8="",0,1)),I8&" ","")&IF(AND(7>=(IF(M8=1,2,1)+AD8),7<=C8-IF(S8="",0,1)),J8&" ","")&IF(AND(8>=(IF(M8=1,2,1)+AD8),8<=C8-IF(S8="",0,1)),K8&" ",""))) | R8: =IF(Q8="","",IFERROR(INDEX(資格マスタ!$B:$B,MATCH(ASC(SUBSTITUTE(SUBSTITUTE(Q8," ","")," ","")),資格マスタ!$D:$D,0)),Q8)) | S8: =IF(C8<2,"",IFERROR(IF(OR(LEFT(INDEX(D8:K8,MIN(8,MAX(1,C8))),2)="令和",LEFT(INDEX(D8:K8,MIN(8,MAX(1,C8))),2)="平成",LEFT(INDEX(D8:K8,MIN(8,MAX(1,C8))),2)="昭和"),DATE(VALUE(MID(INDEX(D8:K8,MIN(8,MAX(1,C8))),3,FIND("年",INDEX(D8:K8,MIN(8,MAX(1,C8))))-3))+IF(LEFT(INDEX(D8:K8,MIN(8,MAX(1,C8))),2)="令和",2018,IF(LEFT(INDEX(D8:K8,MIN(8,MAX(1,C8))),2)="平成",1988,1925)),VALUE(MID(INDEX(D8:K8,MIN(8,MAX(1,C8))),FIND("年",INDEX(D8:K8,MIN(8,MAX(1,C8))))+1,FIND("月",INDEX(D8:K8,MIN(8,MAX(1,C8))))-FIND("年",INDEX(D8:K8,MIN(8,MAX(1,C8))))-1)),VALUE(SUBSTITUTE(MID(INDEX(D8:K8,MIN(8,MAX(1,C8))),FIND("月",INDEX(D8:K8,MIN(8,MAX(1,C8))))+1,10),"日",""))),DATE(VALUE(TRIM(MID(SUBSTITUTE(AA8,"/",REPT(" ",50)),1,50))),VALUE(TRIM(MID(SUBSTITUTE(AA8,"/",REPT(" ",50)),51,50))),VALUE(TRIM(MID(SUBSTITUTE(AA8,"/",REPT(" ",50)),101,50))))),IFERROR(DATEVALUE(INDEX(D8:K8,MIN(8,MAX(1,C8)))),""))) | T8: =IF(B8="","",IF(AB8<>"",AB8,IFERROR(MATCH(SUBSTITUTE(SUBSTITUTE(P8," ","")," ",""),入力!$AJ$5:$AJ$44,0),""))) | U8: =IF(T8="","",INDEX(入力!$D$5:$D$44,T8)) | V8: =IF(B8="","",IF(T8="","要確認（名簿と照合できません）",IF(R8="","要確認（資格名がありません）",IF(S8="","要確認（取得日が読めません）",IF((IF(INDEX(入力!$N$5:$N$44,T8)=R8,1,0)+IF(INDEX(入力!$P$5:$P$44,T8)=R8,1,0)+IF(INDEX(入力!$R$5:$R$44,T8)=R8,1,0)+IF(INDEX(入力!$T$5:$T$44,T8)=R8,1,0)+IF(INDEX(入力!$V$5:$V$44,T8)=R8,1,0)+IF(INDEX(入力!$X$5:$X$44,T8)=R8,1,0))+(COUNTIFS($T$6:$T$205,T8,$R$6:$R$205,R8,$X$6:$X$205,"<"&X8))>0,"重複","反映"))))) | W8: =IF(V8="反映",1,0) | X8: 8 | Y8: =IF(W8=0,"",COUNTIFS($T$6:$T$205,T8,$W$6:$W$205,1,$S$6:$S$205,"<"&S8)+COUNTIFS($T$6:$T$205,T8,$W$6:$W$205,1,$S$6:$S$205,S8,$X$6:$X$205,"<"&X8)+1) | Z8: =IF(Y8="","",T8&"_"&Y8) | AA8: =SUBSTITUTE(SUBSTITUTE(SUBSTITUTE(SUBSTITUTE(SUBSTITUTE(INDEX(D8:K8,MIN(8,MAX(1,C8))),"年","/"),"月","/"),"日",""),"-","/"),".","/") | AB8: =IFERROR(MATCH(O8,入力!$C$5:$C$44,0),"") | AC8: =IF(AB8="","",INDEX(入力!$AJ$5:$AJ$44,AB8)) | AD8: =IF(INDEX($D8:$K8,IF(M8=1,2,1))=AC8,1,IF(INDEX($D8:$K8,IF(M8=1,2,1))&INDEX($D8:$K8,IF(M8=1,2,1)+1)=AC8,2,IF(INDEX($D8:$K8,IF(M8=1,2,1))&INDEX($D8:$K8,IF(M8=1,2,1)+1)&INDEX($D8:$K8,IF(M8=1,2,1)+2)=AC8,3,IF(AB8<>"",2,IF(ISNUMBER(MATCH(INDEX($D8:$K8,IF(M8=1,2,1)),入力!$AJ$5:$AJ$44,0)),1,IF(ISNUMBER(MATCH(INDEX($D8:$K8,IF(M8=1,2,1))&INDEX($D8:$K8,IF(M8=1,2,1)+1),入力!$AJ$5:$AJ$44,0)),2,IF(ISNUMBER(MATCH(INDEX($D8:$K8,IF(M8=1,2,1))&INDEX($D8:$K8,IF(M8=1,2,1)+1)&INDEX($D8:$K8,IF(M8=1,2,1)+2),入力!$AJ$5:$AJ$44,0)),3,2)))))))
A9: 3-2-2 近畿 花子 技能検定 機械加工（普通旋盤作業）3級 令和7年7月13日 | B9: =TRIM(SUBSTITUTE(SUBSTITUTE(SUBSTITUTE(A9,CHAR(9)," ")," "," "),CHAR(160)," ")) | C9: =IF(B9="",0,LEN(B9)-LEN(SUBSTITUTE(B9," ",""))+1) | D9: =IF(C9>=1,TRIM(MID(SUBSTITUTE(B9," ",REPT(" ",200)),1,200)),"") | E9: =IF(C9>=2,TRIM(MID(SUBSTITUTE(B9," ",REPT(" ",200)),201,200)),"") | F9: =IF(C9>=3,TRIM(MID(SUBSTITUTE(B9," ",REPT(" ",200)),401,200)),"") | G9: =IF(C9>=4,TRIM(MID(SUBSTITUTE(B9," ",REPT(" ",200)),601,200)),"") | H9: =IF(C9>=5,TRIM(MID(SUBSTITUTE(B9," ",REPT(" ",200)),801,200)),"") | I9: =IF(C9>=6,TRIM(MID(SUBSTITUTE(B9," ",REPT(" ",200)),1001,200)),"") | J9: =IF(C9>=7,TRIM(MID(SUBSTITUTE(B9," ",REPT(" ",200)),1201,200)),"") | K9: =IF(C9>=8,TRIM(MID(SUBSTITUTE(B9," ",REPT(" ",200)),1401,200)),"") | L9: =SUBSTITUTE(SUBSTITUTE(SUBSTITUTE(D9,"年","-"),"組","-"),"番","") | M9: =IF(D9="",0,IF(ISNUMBER(VALUE(SUBSTITUTE(L9,"-",""))),1,0)) | N9: =IF(M9=0,"",IFERROR(VALUE(TRIM(MID(SUBSTITUTE(L9,"-",REPT(" ",100)),101,100))),"")) | O9: =IF(M9=0,"",IFERROR(VALUE(TRIM(RIGHT(SUBSTITUTE(L9,"-",REPT(" ",100)),100))),"")) | P9: =IF(B9="","",TRIM(INDEX($D9:$K9,IF(M9=1,2,1))&IF(AD9>=2," "&INDEX($D9:$K9,IF(M9=1,2,1)+1),"")&IF(AD9>=3," "&INDEX($D9:$K9,IF(M9=1,2,1)+2),""))) | Q9: =IF(C9<2,"",TRIM(IF(AND(2>=(IF(M9=1,2,1)+AD9),2<=C9-IF(S9="",0,1)),E9&" ","")&IF(AND(3>=(IF(M9=1,2,1)+AD9),3<=C9-IF(S9="",0,1)),F9&" ","")&IF(AND(4>=(IF(M9=1,2,1)+AD9),4<=C9-IF(S9="",0,1)),G9&" ","")&IF(AND(5>=(IF(M9=1,2,1)+AD9),5<=C9-IF(S9="",0,1)),H9&" ","")&IF(AND(6>=(IF(M9=1,2,1)+AD9),6<=C9-IF(S9="",0,1)),I9&" ","")&IF(AND(7>=(IF(M9=1,2,1)+AD9),7<=C9-IF(S9="",0,1)),J9&" ","")&IF(AND(8>=(IF(M9=1,2,1)+AD9),8<=C9-IF(S9="",0,1)),K9&" ",""))) | R9: =IF(Q9="","",IFERROR(INDEX(資格マスタ!$B:$B,MATCH(ASC(SUBSTITUTE(SUBSTITUTE(Q9," ","")," ","")),資格マスタ!$D:$D,0)),Q9)) | S9: =IF(C9<2,"",IFERROR(IF(OR(LEFT(INDEX(D9:K9,MIN(8,MAX(1,C9))),2)="令和",LEFT(INDEX(D9:K9,MIN(8,MAX(1,C9))),2)="平成",LEFT(INDEX(D9:K9,MIN(8,MAX(1,C9))),2)="昭和"),DATE(VALUE(MID(INDEX(D9:K9,MIN(8,MAX(1,C9))),3,FIND("年",INDEX(D9:K9,MIN(8,MAX(1,C9))))-3))+IF(LEFT(INDEX(D9:K9,MIN(8,MAX(1,C9))),2)="令和",2018,IF(LEFT(INDEX(D9:K9,MIN(8,MAX(1,C9))),2)="平成",1988,1925)),VALUE(MID(INDEX(D9:K9,MIN(8,MAX(1,C9))),FIND("年",INDEX(D9:K9,MIN(8,MAX(1,C9))))+1,FIND("月",INDEX(D9:K9,MIN(8,MAX(1,C9))))-FIND("年",INDEX(D9:K9,MIN(8,MAX(1,C9))))-1)),VALUE(SUBSTITUTE(MID(INDEX(D9:K9,MIN(8,MAX(1,C9))),FIND("月",INDEX(D9:K9,MIN(8,MAX(1,C9))))+1,10),"日",""))),DATE(VALUE(TRIM(MID(SUBSTITUTE(AA9,"/",REPT(" ",50)),1,50))),VALUE(TRIM(MID(SUBSTITUTE(AA9,"/",REPT(" ",50)),51,50))),VALUE(TRIM(MID(SUBSTITUTE(AA9,"/",REPT(" ",50)),101,50))))),IFERROR(DATEVALUE(INDEX(D9:K9,MIN(8,MAX(1,C9)))),""))) | T9: =IF(B9="","",IF(AB9<>"",AB9,IFERROR(MATCH(SUBSTITUTE(SUBSTITUTE(P9," ","")," ",""),入力!$AJ$5:$AJ$44,0),""))) | U9: =IF(T9="","",INDEX(入力!$D$5:$D$44,T9)) | V9: =IF(B9="","",IF(T9="","要確認（名簿と照合できません）",IF(R9="","要確認（資格名がありません）",IF(S9="","要確認（取得日が読めません）",IF((IF(INDEX(入力!$N$5:$N$44,T9)=R9,1,0)+IF(INDEX(入力!$P$5:$P$44,T9)=R9,1,0)+IF(INDEX(入力!$R$5:$R$44,T9)=R9,1,0)+IF(INDEX(入力!$T$5:$T$44,T9)=R9,1,0)+IF(INDEX(入力!$V$5:$V$44,T9)=R9,1,0)+IF(INDEX(入力!$X$5:$X$44,T9)=R9,1,0))+(COUNTIFS($T$6:$T$205,T9,$R$6:$R$205,R9,$X$6:$X$205,"<"&X9))>0,"重複","反映"))))) | W9: =IF(V9="反映",1,0) | X9: 9 | Y9: =IF(W9=0,"",COUNTIFS($T$6:$T$205,T9,$W$6:$W$205,1,$S$6:$S$205,"<"&S9)+COUNTIFS($T$6:$T$205,T9,$W$6:$W$205,1,$S$6:$S$205,S9,$X$6:$X$205,"<"&X9)+1) | Z9: =IF(Y9="","",T9&"_"&Y9) | AA9: =SUBSTITUTE(SUBSTITUTE(SUBSTITUTE(SUBSTITUTE(SUBSTITUTE(INDEX(D9:K9,MIN(8,MAX(1,C9))),"年","/"),"月","/"),"日",""),"-","/"),".","/") | AB9: =IFERROR(MATCH(O9,入力!$C$5:$C$44,0),"") | AC9: =IF(AB9="","",INDEX(入力!$AJ$5:$AJ$44,AB9)) | AD9: =IF(INDEX($D9:$K9,IF(M9=1,2,1))=AC9,1,IF(INDEX($D9:$K9,IF(M9=1,2,1))&INDEX($D9:$K9,IF(M9=1,2,1)+1)=AC9,2,IF(INDEX($D9:$K9,IF(M9=1,2,1))&INDEX($D9:$K9,IF(M9=1,2,1)+1)&INDEX($D9:$K9,IF(M9=1,2,1)+2)=AC9,3,IF(AB9<>"",2,IF(ISNUMBER(MATCH(INDEX($D9:$K9,IF(M9=1,2,1)),入力!$AJ$5:$AJ$44,0)),1,IF(ISNUMBER(MATCH(INDEX($D9:$K9,IF(M9=1,2,1))&INDEX($D9:$K9,IF(M9=1,2,1)+1),入力!$AJ$5:$AJ$44,0)),2,IF(ISNUMBER(MATCH(INDEX($D9:$K9,IF(M9=1,2,1))&INDEX($D9:$K9,IF(M9=1,2,1)+1)&INDEX($D9:$K9,IF(M9=1,2,1)+2),入力!$AJ$5:$AJ$44,0)),3,2)))))))
B10: =TRIM(SUBSTITUTE(SUBSTITUTE(SUBSTITUTE(A10,CHAR(9)," ")," "," "),CHAR(160)," ")) | C10: =IF(B10="",0,LEN(B10)-LEN(SUBSTITUTE(B10," ",""))+1) | D10: =IF(C10>=1,TRIM(MID(SUBSTITUTE(B10," ",REPT(" ",200)),1,200)),"") | E10: =IF(C10>=2,TRIM(MID(SUBSTITUTE(B10," ",REPT(" ",200)),201,200)),"") | F10: =IF(C10>=3,TRIM(MID(SUBSTITUTE(B10," ",REPT(" ",200)),401,200)),"") | G10: =IF(C10>=4,TRIM(MID(SUBSTITUTE(B10," ",REPT(" ",200)),601,200)),"") | H10: =IF(C10>=5,TRIM(MID(SUBSTITUTE(B10," ",REPT(" ",200)),801,200)),"") | I10: =IF(C10>=6,TRIM(MID(SUBSTITUTE(B10," ",REPT(" ",200)),1001,200)),"") | J10: =IF(C10>=7,TRIM(MID(SUBSTITUTE(B10," ",REPT(" ",200)),1201,200)),"") | K10: =IF(C10>=8,TRIM(MID(SUBSTITUTE(B10," ",REPT(" ",200)),1401,200)),"") | L10: =SUBSTITUTE(SUBSTITUTE(SUBSTITUTE(D10,"年","-"),"組","-"),"番","") | M10: =IF(D10="",0,IF(ISNUMBER(VALUE(SUBSTITUTE(L10,"-",""))),1,0)) | N10: =IF(M10=0,"",IFERROR(VALUE(TRIM(MID(SUBSTITUTE(L10,"-",REPT(" ",100)),101,100))),"")) | O10: =IF(M10=0,"",IFERROR(VALUE(TRIM(RIGHT(SUBSTITUTE(L10,"-",REPT(" ",100)),100))),"")) | P10: =IF(B10="","",TRIM(INDEX($D10:$K10,IF(M10=1,2,1))&IF(AD10>=2," "&INDEX($D10:$K10,IF(M10=1,2,1)+1),"")&IF(AD10>=3," "&INDEX($D10:$K10,IF(M10=1,2,1)+2),""))) | Q10: =IF(C10<2,"",TRIM(IF(AND(2>=(IF(M10=1,2,1)+AD10),2<=C10-IF(S10="",0,1)),E10&" ","")&IF(AND(3>=(IF(M10=1,2,1)+AD10),3<=C10-IF(S10="",0,1)),F10&" ","")&IF(AND(4>=(IF(M10=1,2,1)+AD10),4<=C10-IF(S10="",0,1)),G10&" ","")&IF(AND(5>=(IF(M10=1,2,1)+AD10),5<=C10-IF(S10="",0,1)),H10&" ","")&IF(AND(6>=(IF(M10=1,2,1)+AD10),6<=C10-IF(S10="",0,1)),I10&" ","")&IF(AND(7>=(IF(M10=1,2,1)+AD10),7<=C10-IF(S10="",0,1)),J10&" ","")&IF(AND(8>=(IF(M10=1,2,1)+AD10),8<=C10-IF(S10="",0,1)),K10&" ",""))) | R10: =IF(Q10="","",IFERROR(INDEX(資格マスタ!$B:$B,MATCH(ASC(SUBSTITUTE(SUBSTITUTE(Q10," ","")," ","")),資格マスタ!$D:$D,0)),Q10)) | S10: =IF(C10<2,"",IFERROR(IF(OR(LEFT(INDEX(D10:K10,MIN(8,MAX(1,C10))),2)="令和",LEFT(INDEX(D10:K10,MIN(8,MAX(1,C10))),2)="平成",LEFT(INDEX(D10:K10,MIN(8,MAX(1,C10))),2)="昭和"),DATE(VALUE(MID(INDEX(D10:K10,MIN(8,MAX(1,C10))),3,FIND("年",INDEX(D10:K10,MIN(8,MAX(1,C10))))-3))+IF(LEFT(INDEX(D10:K10,MIN(8,MAX(1,C10))),2)="令和",2018,IF(LEFT(INDEX(D10:K10,MIN(8,MAX(1,C10))),2)="平成",1988,1925)),VALUE(MID(INDEX(D10:K10,MIN(8,MAX(1,C10))),FIND("年",INDEX(D10:K10,MIN(8,MAX(1,C10))))+1,FIND("月",INDEX(D10:K10,MIN(8,MAX(1,C10))))-FIND("年",INDEX(D10:K10,MIN(8,MAX(1,C10))))-1)),VALUE(SUBSTITUTE(MID(INDEX(D10:K10,MIN(8,MAX(1,C10))),FIND("月",INDEX(D10:K10,MIN(8,MAX(1,C10))))+1,10),"日",""))),DATE(VALUE(TRIM(MID(SUBSTITUTE(AA10,"/",REPT(" ",50)),1,50))),VALUE(TRIM(MID(SUBSTITUTE(AA10,"/",REPT(" ",50)),51,50))),VALUE(TRIM(MID(SUBSTITUTE(AA10,"/",REPT(" ",50)),101,50))))),IFERROR(DATEVALUE(INDEX(D10:K10,MIN(8,MAX(1,C10)))),""))) | T10: =IF(B10="","",IF(AB10<>"",AB10,IFERROR(MATCH(SUBSTITUTE(SUBSTITUTE(P10," ","")," ",""),入力!$AJ$5:$AJ$44,0),""))) | U10: =IF(T10="","",INDEX(入力!$D$5:$D$44,T10)) | V10: =IF(B10="","",IF(T10="","要確認（名簿と照合できません）",IF(R10="","要確認（資格名がありません）",IF(S10="","要確認（取得日が読めません）",IF((IF(INDEX(入力!$N$5:$N$44,T10)=R10,1,0)+IF(INDEX(入力!$P$5:$P$44,T10)=R10,1,0)+IF(INDEX(入力!$R$5:$R$44,T10)=R10,1,0)+IF(INDEX(入力!$T$5:$T$44,T10)=R10,1,0)+IF(INDEX(入力!$V$5:$V$44,T10)=R10,1,0)+IF(INDEX(入力!$X$5:$X$44,T10)=R10,1,0))+(COUNTIFS($T$6:$T$205,T10,$R$6:$R$205,R10,$X$6:$X$205,"<"&X10))>0,"重複","反映"))))) | W10: =IF(V10="反映",1,0) | X10: 10 | Y10: =IF(W10=0,"",COUNTIFS($T$6:$T$205,T10,$W$6:$W$205,1,$S$6:$S$205,"<"&S10)+COUNTIFS($T$6:$T$205,T10,$W$6:$W$205,1,$S$6:$S$205,S10,$X$6:$X$205,"<"&X10)+1) | Z10: =IF(Y10="","",T10&"_"&Y10) | AA10: =SUBSTITUTE(SUBSTITUTE(SUBSTITUTE(SUBSTITUTE(SUBSTITUTE(INDEX(D10:K10,MIN(8,MAX(1,C10))),"年","/"),"月","/"),"日",""),"-","/"),".","/") | AB10: =IFERROR(MATCH(O10,入力!$C$5:$C$44,0),"") | AC10: =IF(AB10="","",INDEX(入力!$AJ$5:$AJ$44,AB10)) | AD10: =IF(INDEX($D10:$K10,IF(M10=1,2,1))=AC10,1,IF(INDEX($D10:$K10,IF(M10=1,2,1))&INDEX($D10:$K10,IF(M10=1,2,1)+1)=AC10,2,IF(INDEX($D10:$K10,IF(M10=1,2,1))&INDEX($D10:$K10,IF(M10=1,2,1)+1)&INDEX($D10:$K10,IF(M10=1,2,1)+2)=AC10,3,IF(AB10<>"",2,IF(ISNUMBER(MATCH(INDEX($D10:$K10,IF(M10=1,2,1)),入力!$AJ$5:$AJ$44,0)),1,IF(ISNUMBER(MATCH(INDEX($D10:$K10,IF(M10=1,2,1))&INDEX($D10:$K10,IF(M10=1,2,1)+1),入力!$AJ$5:$AJ$44,0)),2,IF(ISNUMBER(MATCH(INDEX($D10:$K10,IF(M10=1,2,1))&INDEX($D10:$K10,IF(M10=1,2,1)+1)&INDEX($D10:$K10,IF(M10=1,2,1)+2),入力!$AJ$5:$AJ$44,0)),3,2)))))))
B11: =TRIM(SUBSTITUTE(SUBSTITUTE(SUBSTITUTE(A11,CHAR(9)," ")," "," "),CHAR(160)," ")) | C11: =IF(B11="",0,LEN(B11)-LEN(SUBSTITUTE(B11," ",""))+1) | D11: =IF(C11>=1,TRIM(MID(SUBSTITUTE(B11," ",REPT(" ",200)),1,200)),"") | E11: =IF(C11>=2,TRIM(MID(SUBSTITUTE(B11," ",REPT(" ",200)),201,200)),"") | F11: =IF(C11>=3,TRIM(MID(SUBSTITUTE(B11," ",REPT(" ",200)),401,200)),"") | G11: =IF(C11>=4,TRIM(MID(SUBSTITUTE(B11," ",REPT(" ",200)),601,200)),"") | H11: =IF(C11>=5,TRIM(MID(SUBSTITUTE(B11," ",REPT(" ",200)),801,200)),"") | I11: =IF(C11>=6,TRIM(MID(SUBSTITUTE(B11," ",REPT(" ",200)),1001,200)),"") | J11: =IF(C11>=7,TRIM(MID(SUBSTITUTE(B11," ",REPT(" ",200)),1201,200)),"") | K11: =IF(C11>=8,TRIM(MID(SUBSTITUTE(B11," ",REPT(" ",200)),1401,200)),"") | L11: =SUBSTITUTE(SUBSTITUTE(SUBSTITUTE(D11,"年","-"),"組","-"),"番","") | M11: =IF(D11="",0,IF(ISNUMBER(VALUE(SUBSTITUTE(L11,"-",""))),1,0)) | N11: =IF(M11=0,"",IFERROR(VALUE(TRIM(MID(SUBSTITUTE(L11,"-",REPT(" ",100)),101,100))),"")) | O11: =IF(M11=0,"",IFERROR(VALUE(TRIM(RIGHT(SUBSTITUTE(L11,"-",REPT(" ",100)),100))),"")) | P11: =IF(B11="","",TRIM(INDEX($D11:$K11,IF(M11=1,2,1))&IF(AD11>=2," "&INDEX($D11:$K11,IF(M11=1,2,1)+1),"")&IF(AD11>=3," "&INDEX($D11:$K11,IF(M11=1,2,1)+2),""))) | Q11: =IF(C11<2,"",TRIM(IF(AND(2>=(IF(M11=1,2,1)+AD11),2<=C11-IF(S11="",0,1)),E11&" ","")&IF(AND(3>=(IF(M11=1,2,1)+AD11),3<=C11-IF(S11="",0,1)),F11&" ","")&IF(AND(4>=(IF(M11=1,2,1)+AD11),4<=C11-IF(S11="",0,1)),G11&" ","")&IF(AND(5>=(IF(M11=1,2,1)+AD11),5<=C11-IF(S11="",0,1)),H11&" ","")&IF(AND(6>=(IF(M11=1,2,1)+AD11),6<=C11-IF(S11="",0,1)),I11&" ","")&IF(AND(7>=(IF(M11=1,2,1)+AD11),7<=C11-IF(S11="",0,1)),J11&" ","")&IF(AND(8>=(IF(M11=1,2,1)+AD11),8<=C11-IF(S11="",0,1)),K11&" ",""))) | R11: =IF(Q11="","",IFERROR(INDEX(資格マスタ!$B:$B,MATCH(ASC(SUBSTITUTE(SUBSTITUTE(Q11," ","")," ","")),資格マスタ!$D:$D,0)),Q11)) | S11: =IF(C11<2,"",IFERROR(IF(OR(LEFT(INDEX(D11:K11,MIN(8,MAX(1,C11))),2)="令和",LEFT(INDEX(D11:K11,MIN(8,MAX(1,C11))),2)="平成",LEFT(INDEX(D11:K11,MIN(8,MAX(1,C11))),2)="昭和"),DATE(VALUE(MID(INDEX(D11:K11,MIN(8,MAX(1,C11))),3,FIND("年",INDEX(D11:K11,MIN(8,MAX(1,C11))))-3))+IF(LEFT(INDEX(D11:K11,MIN(8,MAX(1,C11))),2)="令和",2018,IF(LEFT(INDEX(D11:K11,MIN(8,MAX(1,C11))),2)="平成",1988,1925)),VALUE(MID(INDEX(D11:K11,MIN(8,MAX(1,C11))),FIND("年",INDEX(D11:K11,MIN(8,MAX(1,C11))))+1,FIND("月",INDEX(D11:K11,MIN(8,MAX(1,C11))))-FIND("年",INDEX(D11:K11,MIN(8,MAX(1,C11))))-1)),VALUE(SUBSTITUTE(MID(INDEX(D11:K11,MIN(8,MAX(1,C11))),FIND("月",INDEX(D11:K11,MIN(8,MAX(1,C11))))+1,10),"日",""))),DATE(VALUE(TRIM(MID(SUBSTITUTE(AA11,"/",REPT(" ",50)),1,50))),VALUE(TRIM(MID(SUBSTITUTE(AA11,"/",REPT(" ",50)),51,50))),VALUE(TRIM(MID(SUBSTITUTE(AA11,"/",REPT(" ",50)),101,50))))),IFERROR(DATEVALUE(INDEX(D11:K11,MIN(8,MAX(1,C11)))),""))) | T11: =IF(B11="","",IF(AB11<>"",AB11,IFERROR(MATCH(SUBSTITUTE(SUBSTITUTE(P11," ","")," ",""),入力!$AJ$5:$AJ$44,0),""))) | U11: =IF(T11="","",INDEX(入力!$D$5:$D$44,T11)) | V11: =IF(B11="","",IF(T11="","要確認（名簿と照合できません）",IF(R11="","要確認（資格名がありません）",IF(S11="","要確認（取得日が読めません）",IF((IF(INDEX(入力!$N$5:$N$44,T11)=R11,1,0)+IF(INDEX(入力!$P$5:$P$44,T11)=R11,1,0)+IF(INDEX(入力!$R$5:$R$44,T11)=R11,1,0)+IF(INDEX(入力!$T$5:$T$44,T11)=R11,1,0)+IF(INDEX(入力!$V$5:$V$44,T11)=R11,1,0)+IF(INDEX(入力!$X$5:$X$44,T11)=R11,1,0))+(COUNTIFS($T$6:$T$205,T11,$R$6:$R$205,R11,$X$6:$X$205,"<"&X11))>0,"重複","反映"))))) | W11: =IF(V11="反映",1,0) | X11: 11 | Y11: =IF(W11=0,"",COUNTIFS($T$6:$T$205,T11,$W$6:$W$205,1,$S$6:$S$205,"<"&S11)+COUNTIFS($T$6:$T$205,T11,$W$6:$W$205,1,$S$6:$S$205,S11,$X$6:$X$205,"<"&X11)+1) | Z11: =IF(Y11="","",T11&"_"&Y11) | AA11: =SUBSTITUTE(SUBSTITUTE(SUBSTITUTE(SUBSTITUTE(SUBSTITUTE(INDEX(D11:K11,MIN(8,MAX(1,C11))),"年","/"),"月","/"),"日",""),"-","/"),".","/") | AB11: =IFERROR(MATCH(O11,入力!$C$5:$C$44,0),"") | AC11: =IF(AB11="","",INDEX(入力!$AJ$5:$AJ$44,AB11)) | AD11: =IF(INDEX($D11:$K11,IF(M11=1,2,1))=AC11,1,IF(INDEX($D11:$K11,IF(M11=1,2,1))&INDEX($D11:$K11,IF(M11=1,2,1)+1)=AC11,2,IF(INDEX($D11:$K11,IF(M11=1,2,1))&INDEX($D11:$K11,IF(M11=1,2,1)+1)&INDEX($D11:$K11,IF(M11=1,2,1)+2)=AC11,3,IF(AB11<>"",2,IF(ISNUMBER(MATCH(INDEX($D11:$K11,IF(M11=1,2,1)),入力!$AJ$5:$AJ$44,0)),1,IF(ISNUMBER(MATCH(INDEX($D11:$K11,IF(M11=1,2,1))&INDEX($D11:$K11,IF(M11=1,2,1)+1),入力!$AJ$5:$AJ$44,0)),2,IF(ISNUMBER(MATCH(INDEX($D11:$K11,IF(M11=1,2,1))&INDEX($D11:$K11,IF(M11=1,2,1)+1)&INDEX($D11:$K11,IF(M11=1,2,1)+2),入力!$AJ$5:$AJ$44,0)),3,2)))))))
B12: =TRIM(SUBSTITUTE(SUBSTITUTE(SUBSTITUTE(A12,CHAR(9)," ")," "," "),CHAR(160)," ")) | C12: =IF(B12="",0,LEN(B12)-LEN(SUBSTITUTE(B12," ",""))+1) | D12: =IF(C12>=1,TRIM(MID(SUBSTITUTE(B12," ",REPT(" ",200)),1,200)),"") | E12: =IF(C12>=2,TRIM(MID(SUBSTITUTE(B12," ",REPT(" ",200)),201,200)),"") | F12: =IF(C12>=3,TRIM(MID(SUBSTITUTE(B12," ",REPT(" ",200)),401,200)),"") | G12: =IF(C12>=4,TRIM(MID(SUBSTITUTE(B12," ",REPT(" ",200)),601,200)),"") | H12: =IF(C12>=5,TRIM(MID(SUBSTITUTE(B12," ",REPT(" ",200)),801,200)),"") | I12: =IF(C12>=6,TRIM(MID(SUBSTITUTE(B12," ",REPT(" ",200)),1001,200)),"") | J12: =IF(C12>=7,TRIM(MID(SUBSTITUTE(B12," ",REPT(" ",200)),1201,200)),"") | K12: =IF(C12>=8,TRIM(MID(SUBSTITUTE(B12," ",REPT(" ",200)),1401,200)),"") | L12: =SUBSTITUTE(SUBSTITUTE(SUBSTITUTE(D12,"年","-"),"組","-"),"番","") | M12: =IF(D12="",0,IF(ISNUMBER(VALUE(SUBSTITUTE(L12,"-",""))),1,0)) | N12: =IF(M12=0,"",IFERROR(VALUE(TRIM(MID(SUBSTITUTE(L12,"-",REPT(" ",100)),101,100))),"")) | O12: =IF(M12=0,"",IFERROR(VALUE(TRIM(RIGHT(SUBSTITUTE(L12,"-",REPT(" ",100)),100))),"")) | P12: =IF(B12="","",TRIM(INDEX($D12:$K12,IF(M12=1,2,1))&IF(AD12>=2," "&INDEX($D12:$K12,IF(M12=1,2,1)+1),"")&IF(AD12>=3," "&INDEX($D12:$K12,IF(M12=1,2,1)+2),""))) | Q12: =IF(C12<2,"",TRIM(IF(AND(2>=(IF(M12=1,2,1)+AD12),2<=C12-IF(S12="",0,1)),E12&" ","")&IF(AND(3>=(IF(M12=1,2,1)+AD12),3<=C12-IF(S12="",0,1)),F12&" ","")&IF(AND(4>=(IF(M12=1,2,1)+AD12),4<=C12-IF(S12="",0,1)),G12&" ","")&IF(AND(5>=(IF(M12=1,2,1)+AD12),5<=C12-IF(S12="",0,1)),H12&" ","")&IF(AND(6>=(IF(M12=1,2,1)+AD12),6<=C12-IF(S12="",0,1)),I12&" ","")&IF(AND(7>=(IF(M12=1,2,1)+AD12),7<=C12-IF(S12="",0,1)),J12&" ","")&IF(AND(8>=(IF(M12=1,2,1)+AD12),8<=C12-IF(S12="",0,1)),K12&" ",""))) | R12: =IF(Q12="","",IFERROR(INDEX(資格マスタ!$B:$B,MATCH(ASC(SUBSTITUTE(SUBSTITUTE(Q12," ","")," ","")),資格マスタ!$D:$D,0)),Q12)) | S12: =IF(C12<2,"",IFERROR(IF(OR(LEFT(INDEX(D12:K12,MIN(8,MAX(1,C12))),2)="令和",LEFT(INDEX(D12:K12,MIN(8,MAX(1,C12))),2)="平成",LEFT(INDEX(D12:K12,MIN(8,MAX(1,C12))),2)="昭和"),DATE(VALUE(MID(INDEX(D12:K12,MIN(8,MAX(1,C12))),3,FIND("年",INDEX(D12:K12,MIN(8,MAX(1,C12))))-3))+IF(LEFT(INDEX(D12:K12,MIN(8,MAX(1,C12))),2)="令和",2018,IF(LEFT(INDEX(D12:K12,MIN(8,MAX(1,C12))),2)="平成",1988,1925)),VALUE(MID(INDEX(D12:K12,MIN(8,MAX(1,C12))),FIND("年",INDEX(D12:K12,MIN(8,MAX(1,C12))))+1,FIND("月",INDEX(D12:K12,MIN(8,MAX(1,C12))))-FIND("年",INDEX(D12:K12,MIN(8,MAX(1,C12))))-1)),VALUE(SUBSTITUTE(MID(INDEX(D12:K12,MIN(8,MAX(1,C12))),FIND("月",INDEX(D12:K12,MIN(8,MAX(1,C12))))+1,10),"日",""))),DATE(VALUE(TRIM(MID(SUBSTITUTE(AA12,"/",REPT(" ",50)),1,50))),VALUE(TRIM(MID(SUBSTITUTE(AA12,"/",REPT(" ",50)),51,50))),VALUE(TRIM(MID(SUBSTITUTE(AA12,"/",REPT(" ",50)),101,50))))),IFERROR(DATEVALUE(INDEX(D12:K12,MIN(8,MAX(1,C12)))),""))) | T12: =IF(B12="","",IF(AB12<>"",AB12,IFERROR(MATCH(SUBSTITUTE(SUBSTITUTE(P12," ","")," ",""),入力!$AJ$5:$AJ$44,0),""))) | U12: =IF(T12="","",INDEX(入力!$D$5:$D$44,T12)) | V12: =IF(B12="","",IF(T12="","要確認（名簿と照合できません）",IF(R12="","要確認（資格名がありません）",IF(S12="","要確認（取得日が読めません）",IF((IF(INDEX(入力!$N$5:$N$44,T12)=R12,1,0)+IF(INDEX(入力!$P$5:$P$44,T12)=R12,1,0)+IF(INDEX(入力!$R$5:$R$44,T12)=R12,1,0)+IF(INDEX(入力!$T$5:$T$44,T12)=R12,1,0)+IF(INDEX(入力!$V$5:$V$44,T12)=R12,1,0)+IF(INDEX(入力!$X$5:$X$44,T12)=R12,1,0))+(COUNTIFS($T$6:$T$205,T12,$R$6:$R$205,R12,$X$6:$X$205,"<"&X12))>0,"重複","反映"))))) | W12: =IF(V12="反映",1,0) | X12: 12 | Y12: =IF(W12=0,"",COUNTIFS($T$6:$T$205,T12,$W$6:$W$205,1,$S$6:$S$205,"<"&S12)+COUNTIFS($T$6:$T$205,T12,$W$6:$W$205,1,$S$6:$S$205,S12,$X$6:$X$205,"<"&X12)+1) | Z12: =IF(Y12="","",T12&"_"&Y12) | AA12: =SUBSTITUTE(SUBSTITUTE(SUBSTITUTE(SUBSTITUTE(SUBSTITUTE(INDEX(D12:K12,MIN(8,MAX(1,C12))),"年","/"),"月","/"),"日",""),"-","/"),".","/") | AB12: =IFERROR(MATCH(O12,入力!$C$5:$C$44,0),"") | AC12: =IF(AB12="","",INDEX(入力!$AJ$5:$AJ$44,AB12)) | AD12: =IF(INDEX($D12:$K12,IF(M12=1,2,1))=AC12,1,IF(INDEX($D12:$K12,IF(M12=1,2,1))&INDEX($D12:$K12,IF(M12=1,2,1)+1)=AC12,2,IF(INDEX($D12:$K12,IF(M12=1,2,1))&INDEX($D12:$K12,IF(M12=1,2,1)+1)&INDEX($D12:$K12,IF(M12=1,2,1)+2)=AC12,3,IF(AB12<>"",2,IF(ISNUMBER(MATCH(INDEX($D12:$K12,IF(M12=1,2,1)),入力!$AJ$5:$AJ$44,0)),1,IF(ISNUMBER(MATCH(INDEX($D12:$K12,IF(M12=1,2,1))&INDEX($D12:$K12,IF(M12=1,2,1)+1),入力!$AJ$5:$AJ$44,0)),2,IF(ISNUMBER(MATCH(INDEX($D12:$K12,IF(M12=1,2,1))&INDEX($D12:$K12,IF(M12=1,2,1)+1)&INDEX($D12:$K12,IF(M12=1,2,1)+2),入力!$AJ$5:$AJ$44,0)),3,2)))))))
B13: =TRIM(SUBSTITUTE(SUBSTITUTE(SUBSTITUTE(A13,CHAR(9)," ")," "," "),CHAR(160)," ")) | C13: =IF(B13="",0,LEN(B13)-LEN(SUBSTITUTE(B13," ",""))+1) | D13: =IF(C13>=1,TRIM(MID(SUBSTITUTE(B13," ",REPT(" ",200)),1,200)),"") | E13: =IF(C13>=2,TRIM(MID(SUBSTITUTE(B13," ",REPT(" ",200)),201,200)),"") | F13: =IF(C13>=3,TRIM(MID(SUBSTITUTE(B13," ",REPT(" ",200)),401,200)),"") | G13: =IF(C13>=4,TRIM(MID(SUBSTITUTE(B13," ",REPT(" ",200)),601,200)),"") | H13: =IF(C13>=5,TRIM(MID(SUBSTITUTE(B13," ",REPT(" ",200)),801,200)),"") | I13: =IF(C13>=6,TRIM(MID(SUBSTITUTE(B13," ",REPT(" ",200)),1001,200)),"") | J13: =IF(C13>=7,TRIM(MID(SUBSTITUTE(B13," ",REPT(" ",200)),1201,200)),"") | K13: =IF(C13>=8,TRIM(MID(SUBSTITUTE(B13," ",REPT(" ",200)),1401,200)),"") | L13: =SUBSTITUTE(SUBSTITUTE(SUBSTITUTE(D13,"年","-"),"組","-"),"番","") | M13: =IF(D13="",0,IF(ISNUMBER(VALUE(SUBSTITUTE(L13,"-",""))),1,0)) | N13: =IF(M13=0,"",IFERROR(VALUE(TRIM(MID(SUBSTITUTE(L13,"-",REPT(" ",100)),101,100))),"")) | O13: =IF(M13=0,"",IFERROR(VALUE(TRIM(RIGHT(SUBSTITUTE(L13,"-",REPT(" ",100)),100))),"")) | P13: =IF(B13="","",TRIM(INDEX($D13:$K13,IF(M13=1,2,1))&IF(AD13>=2," "&INDEX($D13:$K13,IF(M13=1,2,1)+1),"")&IF(AD13>=3," "&INDEX($D13:$K13,IF(M13=1,2,1)+2),""))) | Q13: =IF(C13<2,"",TRIM(IF(AND(2>=(IF(M13=1,2,1)+AD13),2<=C13-IF(S13="",0,1)),E13&" ","")&IF(AND(3>=(IF(M13=1,2,1)+AD13),3<=C13-IF(S13="",0,1)),F13&" ","")&IF(AND(4>=(IF(M13=1,2,1)+AD13),4<=C13-IF(S13="",0,1)),G13&" ","")&IF(AND(5>=(IF(M13=1,2,1)+AD13),5<=C13-IF(S13="",0,1)),H13&" ","")&IF(AND(6>=(IF(M13=1,2,1)+AD13),6<=C13-IF(S13="",0,1)),I13&" ","")&IF(AND(7>=(IF(M13=1,2,1)+AD13),7<=C13-IF(S13="",0,1)),J13&" ","")&IF(AND(8>=(IF(M13=1,2,1)+AD13),8<=C13-IF(S13="",0,1)),K13&" ",""))) | R13: =IF(Q13="","",IFERROR(INDEX(資格マスタ!$B:$B,MATCH(ASC(SUBSTITUTE(SUBSTITUTE(Q13," ","")," ","")),資格マスタ!$D:$D,0)),Q13)) | S13: =IF(C13<2,"",IFERROR(IF(OR(LEFT(INDEX(D13:K13,MIN(8,MAX(1,C13))),2)="令和",LEFT(INDEX(D13:K13,MIN(8,MAX(1,C13))),2)="平成",LEFT(INDEX(D13:K13,MIN(8,MAX(1,C13))),2)="昭和"),DATE(VALUE(MID(INDEX(D13:K13,MIN(8,MAX(1,C13))),3,FIND("年",INDEX(D13:K13,MIN(8,MAX(1,C13))))-3))+IF(LEFT(INDEX(D13:K13,MIN(8,MAX(1,C13))),2)="令和",2018,IF(LEFT(INDEX(D13:K13,MIN(8,MAX(1,C13))),2)="平成",1988,1925)),VALUE(MID(INDEX(D13:K13,MIN(8,MAX(1,C13))),FIND("年",INDEX(D13:K13,MIN(8,MAX(1,C13))))+1,FIND("月",INDEX(D13:K13,MIN(8,MAX(1,C13))))-FIND("年",INDEX(D13:K13,MIN(8,MAX(1,C13))))-1)),VALUE(SUBSTITUTE(MID(INDEX(D13:K13,MIN(8,MAX(1,C13))),FIND("月",INDEX(D13:K13,MIN(8,MAX(1,C13))))+1,10),"日",""))),DATE(VALUE(TRIM(MID(SUBSTITUTE(AA13,"/",REPT(" ",50)),1,50))),VALUE(TRIM(MID(SUBSTITUTE(AA13,"/",REPT(" ",50)),51,50))),VALUE(TRIM(MID(SUBSTITUTE(AA13,"/",REPT(" ",50)),101,50))))),IFERROR(DATEVALUE(INDEX(D13:K13,MIN(8,MAX(1,C13)))),""))) | T13: =IF(B13="","",IF(AB13<>"",AB13,IFERROR(MATCH(SUBSTITUTE(SUBSTITUTE(P13," ","")," ",""),入力!$AJ$5:$AJ$44,0),""))) | U13: =IF(T13="","",INDEX(入力!$D$5:$D$44,T13)) | V13: =IF(B13="","",IF(T13="","要確認（名簿と照合できません）",IF(R13="","要確認（資格名がありません）",IF(S13="","要確認（取得日が読めません）",IF((IF(INDEX(入力!$N$5:$N$44,T13)=R13,1,0)+IF(INDEX(入力!$P$5:$P$44,T13)=R13,1,0)+IF(INDEX(入力!$R$5:$R$44,T13)=R13,1,0)+IF(INDEX(入力!$T$5:$T$44,T13)=R13,1,0)+IF(INDEX(入力!$V$5:$V$44,T13)=R13,1,0)+IF(INDEX(入力!$X$5:$X$44,T13)=R13,1,0))+(COUNTIFS($T$6:$T$205,T13,$R$6:$R$205,R13,$X$6:$X$205,"<"&X13))>0,"重複","反映"))))) | W13: =IF(V13="反映",1,0) | X13: 13 | Y13: =IF(W13=0,"",COUNTIFS($T$6:$T$205,T13,$W$6:$W$205,1,$S$6:$S$205,"<"&S13)+COUNTIFS($T$6:$T$205,T13,$W$6:$W$205,1,$S$6:$S$205,S13,$X$6:$X$205,"<"&X13)+1) | Z13: =IF(Y13="","",T13&"_"&Y13) | AA13: =SUBSTITUTE(SUBSTITUTE(SUBSTITUTE(SUBSTITUTE(SUBSTITUTE(INDEX(D13:K13,MIN(8,MAX(1,C13))),"年","/"),"月","/"),"日",""),"-","/"),".","/") | AB13: =IFERROR(MATCH(O13,入力!$C$5:$C$44,0),"") | AC13: =IF(AB13="","",INDEX(入力!$AJ$5:$AJ$44,AB13)) | AD13: =IF(INDEX($D13:$K13,IF(M13=1,2,1))=AC13,1,IF(INDEX($D13:$K13,IF(M13=1,2,1))&INDEX($D13:$K13,IF(M13=1,2,1)+1)=AC13,2,IF(INDEX($D13:$K13,IF(M13=1,2,1))&INDEX($D13:$K13,IF(M13=1,2,1)+1)&INDEX($D13:$K13,IF(M13=1,2,1)+2)=AC13,3,IF(AB13<>"",2,IF(ISNUMBER(MATCH(INDEX($D13:$K13,IF(M13=1,2,1)),入力!$AJ$5:$AJ$44,0)),1,IF(ISNUMBER(MATCH(INDEX($D13:$K13,IF(M13=1,2,1))&INDEX($D13:$K13,IF(M13=1,2,1)+1),入力!$AJ$5:$AJ$44,0)),2,IF(ISNUMBER(MATCH(INDEX($D13:$K13,IF(M13=1,2,1))&INDEX($D13:$K13,IF(M13=1,2,1)+1)&INDEX($D13:$K13,IF(M13=1,2,1)+2),入力!$AJ$5:$AJ$44,0)),3,2)))))))
B14: =TRIM(SUBSTITUTE(SUBSTITUTE(SUBSTITUTE(A14,CHAR(9)," ")," "," "),CHAR(160)," ")) | C14: =IF(B14="",0,LEN(B14)-LEN(SUBSTITUTE(B14," ",""))+1) | D14: =IF(C14>=1,TRIM(MID(SUBSTITUTE(B14," ",REPT(" ",200)),1,200)),"") | E14: =IF(C14>=2,TRIM(MID(SUBSTITUTE(B14," ",REPT(" ",200)),201,200)),"") | F14: =IF(C14>=3,TRIM(MID(SUBSTITUTE(B14," ",REPT(" ",200)),401,200)),"") | G14: =IF(C14>=4,TRIM(MID(SUBSTITUTE(B14," ",REPT(" ",200)),601,200)),"") | H14: =IF(C14>=5,TRIM(MID(SUBSTITUTE(B14," ",REPT(" ",200)),801,200)),"") | I14: =IF(C14>=6,TRIM(MID(SUBSTITUTE(B14," ",REPT(" ",200)),1001,200)),"") | J14: =IF(C14>=7,TRIM(MID(SUBSTITUTE(B14," ",REPT(" ",200)),1201,200)),"") | K14: =IF(C14>=8,TRIM(MID(SUBSTITUTE(B14," ",REPT(" ",200)),1401,200)),"") | L14: =SUBSTITUTE(SUBSTITUTE(SUBSTITUTE(D14,"年","-"),"組","-"),"番","") | M14: =IF(D14="",0,IF(ISNUMBER(VALUE(SUBSTITUTE(L14,"-",""))),1,0)) | N14: =IF(M14=0,"",IFERROR(VALUE(TRIM(MID(SUBSTITUTE(L14,"-",REPT(" ",100)),101,100))),"")) | O14: =IF(M14=0,"",IFERROR(VALUE(TRIM(RIGHT(SUBSTITUTE(L14,"-",REPT(" ",100)),100))),"")) | P14: =IF(B14="","",TRIM(INDEX($D14:$K14,IF(M14=1,2,1))&IF(AD14>=2," "&INDEX($D14:$K14,IF(M14=1,2,1)+1),"")&IF(AD14>=3," "&INDEX($D14:$K14,IF(M14=1,2,1)+2),""))) | Q14: =IF(C14<2,"",TRIM(IF(AND(2>=(IF(M14=1,2,1)+AD14),2<=C14-IF(S14="",0,1)),E14&" ","")&IF(AND(3>=(IF(M14=1,2,1)+AD14),3<=C14-IF(S14="",0,1)),F14&" ","")&IF(AND(4>=(IF(M14=1,2,1)+AD14),4<=C14-IF(S14="",0,1)),G14&" ","")&IF(AND(5>=(IF(M14=1,2,1)+AD14),5<=C14-IF(S14="",0,1)),H14&" ","")&IF(AND(6>=(IF(M14=1,2,1)+AD14),6<=C14-IF(S14="",0,1)),I14&" ","")&IF(AND(7>=(IF(M14=1,2,1)+AD14),7<=C14-IF(S14="",0,1)),J14&" ","")&IF(AND(8>=(IF(M14=1,2,1)+AD14),8<=C14-IF(S14="",0,1)),K14&" ",""))) | R14: =IF(Q14="","",IFERROR(INDEX(資格マスタ!$B:$B,MATCH(ASC(SUBSTITUTE(SUBSTITUTE(Q14," ","")," ","")),資格マスタ!$D:$D,0)),Q14)) | S14: =IF(C14<2,"",IFERROR(IF(OR(LEFT(INDEX(D14:K14,MIN(8,MAX(1,C14))),2)="令和",LEFT(INDEX(D14:K14,MIN(8,MAX(1,C14))),2)="平成",LEFT(INDEX(D14:K14,MIN(8,MAX(1,C14))),2)="昭和"),DATE(VALUE(MID(INDEX(D14:K14,MIN(8,MAX(1,C14))),3,FIND("年",INDEX(D14:K14,MIN(8,MAX(1,C14))))-3))+IF(LEFT(INDEX(D14:K14,MIN(8,MAX(1,C14))),2)="令和",2018,IF(LEFT(INDEX(D14:K14,MIN(8,MAX(1,C14))),2)="平成",1988,1925)),VALUE(MID(INDEX(D14:K14,MIN(8,MAX(1,C14))),FIND("年",INDEX(D14:K14,MIN(8,MAX(1,C14))))+1,FIND("月",INDEX(D14:K14,MIN(8,MAX(1,C14))))-FIND("年",INDEX(D14:K14,MIN(8,MAX(1,C14))))-1)),VALUE(SUBSTITUTE(MID(INDEX(D14:K14,MIN(8,MAX(1,C14))),FIND("月",INDEX(D14:K14,MIN(8,MAX(1,C14))))+1,10),"日",""))),DATE(VALUE(TRIM(MID(SUBSTITUTE(AA14,"/",REPT(" ",50)),1,50))),VALUE(TRIM(MID(SUBSTITUTE(AA14,"/",REPT(" ",50)),51,50))),VALUE(TRIM(MID(SUBSTITUTE(AA14,"/",REPT(" ",50)),101,50))))),IFERROR(DATEVALUE(INDEX(D14:K14,MIN(8,MAX(1,C14)))),""))) | T14: =IF(B14="","",IF(AB14<>"",AB14,IFERROR(MATCH(SUBSTITUTE(SUBSTITUTE(P14," ","")," ",""),入力!$AJ$5:$AJ$44,0),""))) | U14: =IF(T14="","",INDEX(入力!$D$5:$D$44,T14)) | V14: =IF(B14="","",IF(T14="","要確認（名簿と照合できません）",IF(R14="","要確認（資格名がありません）",IF(S14="","要確認（取得日が読めません）",IF((IF(INDEX(入力!$N$5:$N$44,T14)=R14,1,0)+IF(INDEX(入力!$P$5:$P$44,T14)=R14,1,0)+IF(INDEX(入力!$R$5:$R$44,T14)=R14,1,0)+IF(INDEX(入力!$T$5:$T$44,T14)=R14,1,0)+IF(INDEX(入力!$V$5:$V$44,T14)=R14,1,0)+IF(INDEX(入力!$X$5:$X$44,T14)=R14,1,0))+(COUNTIFS($T$6:$T$205,T14,$R$6:$R$205,R14,$X$6:$X$205,"<"&X14))>0,"重複","反映"))))) | W14: =IF(V14="反映",1,0) | X14: 14 | Y14: =IF(W14=0,"",COUNTIFS($T$6:$T$205,T14,$W$6:$W$205,1,$S$6:$S$205,"<"&S14)+COUNTIFS($T$6:$T$205,T14,$W$6:$W$205,1,$S$6:$S$205,S14,$X$6:$X$205,"<"&X14)+1) | Z14: =IF(Y14="","",T14&"_"&Y14) | AA14: =SUBSTITUTE(SUBSTITUTE(SUBSTITUTE(SUBSTITUTE(SUBSTITUTE(INDEX(D14:K14,MIN(8,MAX(1,C14))),"年","/"),"月","/"),"日",""),"-","/"),".","/") | AB14: =IFERROR(MATCH(O14,入力!$C$5:$C$44,0),"") | AC14: =IF(AB14="","",INDEX(入力!$AJ$5:$AJ$44,AB14)) | AD14: =IF(INDEX($D14:$K14,IF(M14=1,2,1))=AC14,1,IF(INDEX($D14:$K14,IF(M14=1,2,1))&INDEX($D14:$K14,IF(M14=1,2,1)+1)=AC14,2,IF(INDEX($D14:$K14,IF(M14=1,2,1))&INDEX($D14:$K14,IF(M14=1,2,1)+1)&INDEX($D14:$K14,IF(M14=1,2,1)+2)=AC14,3,IF(AB14<>"",2,IF(ISNUMBER(MATCH(INDEX($D14:$K14,IF(M14=1,2,1)),入力!$AJ$5:$AJ$44,0)),1,IF(ISNUMBER(MATCH(INDEX($D14:$K14,IF(M14=1,2,1))&INDEX($D14:$K14,IF(M14=1,2,1)+1),入力!$AJ$5:$AJ$44,0)),2,IF(ISNUMBER(MATCH(INDEX($D14:$K14,IF(M14=1,2,1))&INDEX($D14:$K14,IF(M14=1,2,1)+1)&INDEX($D14:$K14,IF(M14=1,2,1)+2),入力!$AJ$5:$AJ$44,0)),3,2)))))))
B15: =TRIM(SUBSTITUTE(SUBSTITUTE(SUBSTITUTE(A15,CHAR(9)," ")," "," "),CHAR(160)," ")) | C15: =IF(B15="",0,LEN(B15)-LEN(SUBSTITUTE(B15," ",""))+1) | D15: =IF(C15>=1,TRIM(MID(SUBSTITUTE(B15," ",REPT(" ",200)),1,200)),"") | E15: =IF(C15>=2,TRIM(MID(SUBSTITUTE(B15," ",REPT(" ",200)),201,200)),"") | F15: =IF(C15>=3,TRIM(MID(SUBSTITUTE(B15," ",REPT(" ",200)),401,200)),"") | G15: =IF(C15>=4,TRIM(MID(SUBSTITUTE(B15," ",REPT(" ",200)),601,200)),"") | H15: =IF(C15>=5,TRIM(MID(SUBSTITUTE(B15," ",REPT(" ",200)),801,200)),"") | I15: =IF(C15>=6,TRIM(MID(SUBSTITUTE(B15," ",REPT(" ",200)),1001,200)),"") | J15: =IF(C15>=7,TRIM(MID(SUBSTITUTE(B15," ",REPT(" ",200)),1201,200)),"") | K15: =IF(C15>=8,TRIM(MID(SUBSTITUTE(B15," ",REPT(" ",200)),1401,200)),"") | L15: =SUBSTITUTE(SUBSTITUTE(SUBSTITUTE(D15,"年","-"),"組","-"),"番","") | M15: =IF(D15="",0,IF(ISNUMBER(VALUE(SUBSTITUTE(L15,"-",""))),1,0)) | N15: =IF(M15=0,"",IFERROR(VALUE(TRIM(MID(SUBSTITUTE(L15,"-",REPT(" ",100)),101,100))),"")) | O15: =IF(M15=0,"",IFERROR(VALUE(TRIM(RIGHT(SUBSTITUTE(L15,"-",REPT(" ",100)),100))),"")) | P15: =IF(B15="","",TRIM(INDEX($D15:$K15,IF(M15=1,2,1))&IF(AD15>=2," "&INDEX($D15:$K15,IF(M15=1,2,1)+1),"")&IF(AD15>=3," "&INDEX($D15:$K15,IF(M15=1,2,1)+2),""))) | Q15: =IF(C15<2,"",TRIM(IF(AND(2>=(IF(M15=1,2,1)+AD15),2<=C15-IF(S15="",0,1)),E15&" ","")&IF(AND(3>=(IF(M15=1,2,1)+AD15),3<=C15-IF(S15="",0,1)),F15&" ","")&IF(AND(4>=(IF(M15=1,2,1)+AD15),4<=C15-IF(S15="",0,1)),G15&" ","")&IF(AND(5>=(IF(M15=1,2,1)+AD15),5<=C15-IF(S15="",0,1)),H15&" ","")&IF(AND(6>=(IF(M15=1,2,1)+AD15),6<=C15-IF(S15="",0,1)),I15&" ","")&IF(AND(7>=(IF(M15=1,2,1)+AD15),7<=C15-IF(S15="",0,1)),J15&" ","")&IF(AND(8>=(IF(M15=1,2,1)+AD15),8<=C15-IF(S15="",0,1)),K15&" ",""))) | R15: =IF(Q15="","",IFERROR(INDEX(資格マスタ!$B:$B,MATCH(ASC(SUBSTITUTE(SUBSTITUTE(Q15," ","")," ","")),資格マスタ!$D:$D,0)),Q15)) | S15: =IF(C15<2,"",IFERROR(IF(OR(LEFT(INDEX(D15:K15,MIN(8,MAX(1,C15))),2)="令和",LEFT(INDEX(D15:K15,MIN(8,MAX(1,C15))),2)="平成",LEFT(INDEX(D15:K15,MIN(8,MAX(1,C15))),2)="昭和"),DATE(VALUE(MID(INDEX(D15:K15,MIN(8,MAX(1,C15))),3,FIND("年",INDEX(D15:K15,MIN(8,MAX(1,C15))))-3))+IF(LEFT(INDEX(D15:K15,MIN(8,MAX(1,C15))),2)="令和",2018,IF(LEFT(INDEX(D15:K15,MIN(8,MAX(1,C15))),2)="平成",1988,1925)),VALUE(MID(INDEX(D15:K15,MIN(8,MAX(1,C15))),FIND("年",INDEX(D15:K15,MIN(8,MAX(1,C15))))+1,FIND("月",INDEX(D15:K15,MIN(8,MAX(1,C15))))-FIND("年",INDEX(D15:K15,MIN(8,MAX(1,C15))))-1)),VALUE(SUBSTITUTE(MID(INDEX(D15:K15,MIN(8,MAX(1,C15))),FIND("月",INDEX(D15:K15,MIN(8,MAX(1,C15))))+1,10),"日",""))),DATE(VALUE(TRIM(MID(SUBSTITUTE(AA15,"/",REPT(" ",50)),1,50))),VALUE(TRIM(MID(SUBSTITUTE(AA15,"/",REPT(" ",50)),51,50))),VALUE(TRIM(MID(SUBSTITUTE(AA15,"/",REPT(" ",50)),101,50))))),IFERROR(DATEVALUE(INDEX(D15:K15,MIN(8,MAX(1,C15)))),""))) | T15: =IF(B15="","",IF(AB15<>"",AB15,IFERROR(MATCH(SUBSTITUTE(SUBSTITUTE(P15," ","")," ",""),入力!$AJ$5:$AJ$44,0),""))) | U15: =IF(T15="","",INDEX(入力!$D$5:$D$44,T15)) | V15: =IF(B15="","",IF(T15="","要確認（名簿と照合できません）",IF(R15="","要確認（資格名がありません）",IF(S15="","要確認（取得日が読めません）",IF((IF(INDEX(入力!$N$5:$N$44,T15)=R15,1,0)+IF(INDEX(入力!$P$5:$P$44,T15)=R15,1,0)+IF(INDEX(入力!$R$5:$R$44,T15)=R15,1,0)+IF(INDEX(入力!$T$5:$T$44,T15)=R15,1,0)+IF(INDEX(入力!$V$5:$V$44,T15)=R15,1,0)+IF(INDEX(入力!$X$5:$X$44,T15)=R15,1,0))+(COUNTIFS($T$6:$T$205,T15,$R$6:$R$205,R15,$X$6:$X$205,"<"&X15))>0,"重複","反映"))))) | W15: =IF(V15="反映",1,0) | X15: 15 | Y15: =IF(W15=0,"",COUNTIFS($T$6:$T$205,T15,$W$6:$W$205,1,$S$6:$S$205,"<"&S15)+COUNTIFS($T$6:$T$205,T15,$W$6:$W$205,1,$S$6:$S$205,S15,$X$6:$X$205,"<"&X15)+1) | Z15: =IF(Y15="","",T15&"_"&Y15) | AA15: =SUBSTITUTE(SUBSTITUTE(SUBSTITUTE(SUBSTITUTE(SUBSTITUTE(INDEX(D15:K15,MIN(8,MAX(1,C15))),"年","/"),"月","/"),"日",""),"-","/"),".","/") | AB15: =IFERROR(MATCH(O15,入力!$C$5:$C$44,0),"") | AC15: =IF(AB15="","",INDEX(入力!$AJ$5:$AJ$44,AB15)) | AD15: =IF(INDEX($D15:$K15,IF(M15=1,2,1))=AC15,1,IF(INDEX($D15:$K15,IF(M15=1,2,1))&INDEX($D15:$K15,IF(M15=1,2,1)+1)=AC15,2,IF(INDEX($D15:$K15,IF(M15=1,2,1))&INDEX($D15:$K15,IF(M15=1,2,1)+1)&INDEX($D15:$K15,IF(M15=1,2,1)+2)=AC15,3,IF(AB15<>"",2,IF(ISNUMBER(MATCH(INDEX($D15:$K15,IF(M15=1,2,1)),入力!$AJ$5:$AJ$44,0)),1,IF(ISNUMBER(MATCH(INDEX($D15:$K15,IF(M15=1,2,1))&INDEX($D15:$K15,IF(M15=1,2,1)+1),入力!$AJ$5:$AJ$44,0)),2,IF(ISNUMBER(MATCH(INDEX($D15:$K15,IF(M15=1,2,1))&INDEX($D15:$K15,IF(M15=1,2,1)+1)&INDEX($D15:$K15,IF(M15=1,2,1)+2),入力!$AJ$5:$AJ$44,0)),3,2)))))))
B16: =TRIM(SUBSTITUTE(SUBSTITUTE(SUBSTITUTE(A16,CHAR(9)," ")," "," "),CHAR(160)," ")) | C16: =IF(B16="",0,LEN(B16)-LEN(SUBSTITUTE(B16," ",""))+1) | D16: =IF(C16>=1,TRIM(MID(SUBSTITUTE(B16," ",REPT(" ",200)),1,200)),"") | E16: =IF(C16>=2,TRIM(MID(SUBSTITUTE(B16," ",REPT(" ",200)),201,200)),"") | F16: =IF(C16>=3,TRIM(MID(SUBSTITUTE(B16," ",REPT(" ",200)),401,200)),"") | G16: =IF(C16>=4,TRIM(MID(SUBSTITUTE(B16," ",REPT(" ",200)),601,200)),"") | H16: =IF(C16>=5,TRIM(MID(SUBSTITUTE(B16," ",REPT(" ",200)),801,200)),"") | I16: =IF(C16>=6,TRIM(MID(SUBSTITUTE(B16," ",REPT(" ",200)),1001,200)),"") | J16: =IF(C16>=7,TRIM(MID(SUBSTITUTE(B16," ",REPT(" ",200)),1201,200)),"") | K16: =IF(C16>=8,TRIM(MID(SUBSTITUTE(B16," ",REPT(" ",200)),1401,200)),"") | L16: =SUBSTITUTE(SUBSTITUTE(SUBSTITUTE(D16,"年","-"),"組","-"),"番","") | M16: =IF(D16="",0,IF(ISNUMBER(VALUE(SUBSTITUTE(L16,"-",""))),1,0)) | N16: =IF(M16=0,"",IFERROR(VALUE(TRIM(MID(SUBSTITUTE(L16,"-",REPT(" ",100)),101,100))),"")) | O16: =IF(M16=0,"",IFERROR(VALUE(TRIM(RIGHT(SUBSTITUTE(L16,"-",REPT(" ",100)),100))),"")) | P16: =IF(B16="","",TRIM(INDEX($D16:$K16,IF(M16=1,2,1))&IF(AD16>=2," "&INDEX($D16:$K16,IF(M16=1,2,1)+1),"")&IF(AD16>=3," "&INDEX($D16:$K16,IF(M16=1,2,1)+2),""))) | Q16: =IF(C16<2,"",TRIM(IF(AND(2>=(IF(M16=1,2,1)+AD16),2<=C16-IF(S16="",0,1)),E16&" ","")&IF(AND(3>=(IF(M16=1,2,1)+AD16),3<=C16-IF(S16="",0,1)),F16&" ","")&IF(AND(4>=(IF(M16=1,2,1)+AD16),4<=C16-IF(S16="",0,1)),G16&" ","")&IF(AND(5>=(IF(M16=1,2,1)+AD16),5<=C16-IF(S16="",0,1)),H16&" ","")&IF(AND(6>=(IF(M16=1,2,1)+AD16),6<=C16-IF(S16="",0,1)),I16&" ","")&IF(AND(7>=(IF(M16=1,2,1)+AD16),7<=C16-IF(S16="",0,1)),J16&" ","")&IF(AND(8>=(IF(M16=1,2,1)+AD16),8<=C16-IF(S16="",0,1)),K16&" ",""))) | R16: =IF(Q16="","",IFERROR(INDEX(資格マスタ!$B:$B,MATCH(ASC(SUBSTITUTE(SUBSTITUTE(Q16," ","")," ","")),資格マスタ!$D:$D,0)),Q16)) | S16: =IF(C16<2,"",IFERROR(IF(OR(LEFT(INDEX(D16:K16,MIN(8,MAX(1,C16))),2)="令和",LEFT(INDEX(D16:K16,MIN(8,MAX(1,C16))),2)="平成",LEFT(INDEX(D16:K16,MIN(8,MAX(1,C16))),2)="昭和"),DATE(VALUE(MID(INDEX(D16:K16,MIN(8,MAX(1,C16))),3,FIND("年",INDEX(D16:K16,MIN(8,MAX(1,C16))))-3))+IF(LEFT(INDEX(D16:K16,MIN(8,MAX(1,C16))),2)="令和",2018,IF(LEFT(INDEX(D16:K16,MIN(8,MAX(1,C16))),2)="平成",1988,1925)),VALUE(MID(INDEX(D16:K16,MIN(8,MAX(1,C16))),FIND("年",INDEX(D16:K16,MIN(8,MAX(1,C16))))+1,FIND("月",INDEX(D16:K16,MIN(8,MAX(1,C16))))-FIND("年",INDEX(D16:K16,MIN(8,MAX(1,C16))))-1)),VALUE(SUBSTITUTE(MID(INDEX(D16:K16,MIN(8,MAX(1,C16))),FIND("月",INDEX(D16:K16,MIN(8,MAX(1,C16))))+1,10),"日",""))),DATE(VALUE(TRIM(MID(SUBSTITUTE(AA16,"/",REPT(" ",50)),1,50))),VALUE(TRIM(MID(SUBSTITUTE(AA16,"/",REPT(" ",50)),51,50))),VALUE(TRIM(MID(SUBSTITUTE(AA16,"/",REPT(" ",50)),101,50))))),IFERROR(DATEVALUE(INDEX(D16:K16,MIN(8,MAX(1,C16)))),""))) | T16: =IF(B16="","",IF(AB16<>"",AB16,IFERROR(MATCH(SUBSTITUTE(SUBSTITUTE(P16," ","")," ",""),入力!$AJ$5:$AJ$44,0),""))) | U16: =IF(T16="","",INDEX(入力!$D$5:$D$44,T16)) | V16: =IF(B16="","",IF(T16="","要確認（名簿と照合できません）",IF(R16="","要確認（資格名がありません）",IF(S16="","要確認（取得日が読めません）",IF((IF(INDEX(入力!$N$5:$N$44,T16)=R16,1,0)+IF(INDEX(入力!$P$5:$P$44,T16)=R16,1,0)+IF(INDEX(入力!$R$5:$R$44,T16)=R16,1,0)+IF(INDEX(入力!$T$5:$T$44,T16)=R16,1,0)+IF(INDEX(入力!$V$5:$V$44,T16)=R16,1,0)+IF(INDEX(入力!$X$5:$X$44,T16)=R16,1,0))+(COUNTIFS($T$6:$T$205,T16,$R$6:$R$205,R16,$X$6:$X$205,"<"&X16))>0,"重複","反映"))))) | W16: =IF(V16="反映",1,0) | X16: 16 | Y16: =IF(W16=0,"",COUNTIFS($T$6:$T$205,T16,$W$6:$W$205,1,$S$6:$S$205,"<"&S16)+COUNTIFS($T$6:$T$205,T16,$W$6:$W$205,1,$S$6:$S$205,S16,$X$6:$X$205,"<"&X16)+1) | Z16: =IF(Y16="","",T16&"_"&Y16) | AA16: =SUBSTITUTE(SUBSTITUTE(SUBSTITUTE(SUBSTITUTE(SUBSTITUTE(INDEX(D16:K16,MIN(8,MAX(1,C16))),"年","/"),"月","/"),"日",""),"-","/"),".","/") | AB16: =IFERROR(MATCH(O16,入力!$C$5:$C$44,0),"") | AC16: =IF(AB16="","",INDEX(入力!$AJ$5:$AJ$44,AB16)) | AD16: =IF(INDEX($D16:$K16,IF(M16=1,2,1))=AC16,1,IF(INDEX($D16:$K16,IF(M16=1,2,1))&INDEX($D16:$K16,IF(M16=1,2,1)+1)=AC16,2,IF(INDEX($D16:$K16,IF(M16=1,2,1))&INDEX($D16:$K16,IF(M16=1,2,1)+1)&INDEX($D16:$K16,IF(M16=1,2,1)+2)=AC16,3,IF(AB16<>"",2,IF(ISNUMBER(MATCH(INDEX($D16:$K16,IF(M16=1,2,1)),入力!$AJ$5:$AJ$44,0)),1,IF(ISNUMBER(MATCH(INDEX($D16:$K16,IF(M16=1,2,1))&INDEX($D16:$K16,IF(M16=1,2,1)+1),入力!$AJ$5:$AJ$44,0)),2,IF(ISNUMBER(MATCH(INDEX($D16:$K16,IF(M16=1,2,1))&INDEX($D16:$K16,IF(M16=1,2,1)+1)&INDEX($D16:$K16,IF(M16=1,2,1)+2),入力!$AJ$5:$AJ$44,0)),3,2)))))))
B17: =TRIM(SUBSTITUTE(SUBSTITUTE(SUBSTITUTE(A17,CHAR(9)," ")," "," "),CHAR(160)," ")) | C17: =IF(B17="",0,LEN(B17)-LEN(SUBSTITUTE(B17," ",""))+1) | D17: =IF(C17>=1,TRIM(MID(SUBSTITUTE(B17," ",REPT(" ",200)),1,200)),"") | E17: =IF(C17>=2,TRIM(MID(SUBSTITUTE(B17," ",REPT(" ",200)),201,200)),"") | F17: =IF(C17>=3,TRIM(MID(SUBSTITUTE(B17," ",REPT(" ",200)),401,200)),"") | G17: =IF(C17>=4,TRIM(MID(SUBSTITUTE(B17," ",REPT(" ",200)),601,200)),"") | H17: =IF(C17>=5,TRIM(MID(SUBSTITUTE(B17," ",REPT(" ",200)),801,200)),"") | I17: =IF(C17>=6,TRIM(MID(SUBSTITUTE(B17," ",REPT(" ",200)),1001,200)),"") | J17: =IF(C17>=7,TRIM(MID(SUBSTITUTE(B17," ",REPT(" ",200)),1201,200)),"") | K17: =IF(C17>=8,TRIM(MID(SUBSTITUTE(B17," ",REPT(" ",200)),1401,200)),"") | L17: =SUBSTITUTE(SUBSTITUTE(SUBSTITUTE(D17,"年","-"),"組","-"),"番","") | M17: =IF(D17="",0,IF(ISNUMBER(VALUE(SUBSTITUTE(L17,"-",""))),1,0)) | N17: =IF(M17=0,"",IFERROR(VALUE(TRIM(MID(SUBSTITUTE(L17,"-",REPT(" ",100)),101,100))),"")) | O17: =IF(M17=0,"",IFERROR(VALUE(TRIM(RIGHT(SUBSTITUTE(L17,"-",REPT(" ",100)),100))),"")) | P17: =IF(B17="","",TRIM(INDEX($D17:$K17,IF(M17=1,2,1))&IF(AD17>=2," "&INDEX($D17:$K17,IF(M17=1,2,1)+1),"")&IF(AD17>=3," "&INDEX($D17:$K17,IF(M17=1,2,1)+2),""))) | Q17: =IF(C17<2,"",TRIM(IF(AND(2>=(IF(M17=1,2,1)+AD17),2<=C17-IF(S17="",0,1)),E17&" ","")&IF(AND(3>=(IF(M17=1,2,1)+AD17),3<=C17-IF(S17="",0,1)),F17&" ","")&IF(AND(4>=(IF(M17=1,2,1)+AD17),4<=C17-IF(S17="",0,1)),G17&" ","")&IF(AND(5>=(IF(M17=1,2,1)+AD17),5<=C17-IF(S17="",0,1)),H17&" ","")&IF(AND(6>=(IF(M17=1,2,1)+AD17),6<=C17-IF(S17="",0,1)),I17&" ","")&IF(AND(7>=(IF(M17=1,2,1)+AD17),7<=C17-IF(S17="",0,1)),J17&" ","")&IF(AND(8>=(IF(M17=1,2,1)+AD17),8<=C17-IF(S17="",0,1)),K17&" ",""))) | R17: =IF(Q17="","",IFERROR(INDEX(資格マスタ!$B:$B,MATCH(ASC(SUBSTITUTE(SUBSTITUTE(Q17," ","")," ","")),資格マスタ!$D:$D,0)),Q17)) | S17: =IF(C17<2,"",IFERROR(IF(OR(LEFT(INDEX(D17:K17,MIN(8,MAX(1,C17))),2)="令和",LEFT(INDEX(D17:K17,MIN(8,MAX(1,C17))),2)="平成",LEFT(INDEX(D17:K17,MIN(8,MAX(1,C17))),2)="昭和"),DATE(VALUE(MID(INDEX(D17:K17,MIN(8,MAX(1,C17))),3,FIND("年",INDEX(D17:K17,MIN(8,MAX(1,C17))))-3))+IF(LEFT(INDEX(D17:K17,MIN(8,MAX(1,C17))),2)="令和",2018,IF(LEFT(INDEX(D17:K17,MIN(8,MAX(1,C17))),2)="平成",1988,1925)),VALUE(MID(INDEX(D17:K17,MIN(8,MAX(1,C17))),FIND("年",INDEX(D17:K17,MIN(8,MAX(1,C17))))+1,FIND("月",INDEX(D17:K17,MIN(8,MAX(1,C17))))-FIND("年",INDEX(D17:K17,MIN(8,MAX(1,C17))))-1)),VALUE(SUBSTITUTE(MID(INDEX(D17:K17,MIN(8,MAX(1,C17))),FIND("月",INDEX(D17:K17,MIN(8,MAX(1,C17))))+1,10),"日",""))),DATE(VALUE(TRIM(MID(SUBSTITUTE(AA17,"/",REPT(" ",50)),1,50))),VALUE(TRIM(MID(SUBSTITUTE(AA17,"/",REPT(" ",50)),51,50))),VALUE(TRIM(MID(SUBSTITUTE(AA17,"/",REPT(" ",50)),101,50))))),IFERROR(DATEVALUE(INDEX(D17:K17,MIN(8,MAX(1,C17)))),""))) | T17: =IF(B17="","",IF(AB17<>"",AB17,IFERROR(MATCH(SUBSTITUTE(SUBSTITUTE(P17," ","")," ",""),入力!$AJ$5:$AJ$44,0),""))) | U17: =IF(T17="","",INDEX(入力!$D$5:$D$44,T17)) | V17: =IF(B17="","",IF(T17="","要確認（名簿と照合できません）",IF(R17="","要確認（資格名がありません）",IF(S17="","要確認（取得日が読めません）",IF((IF(INDEX(入力!$N$5:$N$44,T17)=R17,1,0)+IF(INDEX(入力!$P$5:$P$44,T17)=R17,1,0)+IF(INDEX(入力!$R$5:$R$44,T17)=R17,1,0)+IF(INDEX(入力!$T$5:$T$44,T17)=R17,1,0)+IF(INDEX(入力!$V$5:$V$44,T17)=R17,1,0)+IF(INDEX(入力!$X$5:$X$44,T17)=R17,1,0))+(COUNTIFS($T$6:$T$205,T17,$R$6:$R$205,R17,$X$6:$X$205,"<"&X17))>0,"重複","反映"))))) | W17: =IF(V17="反映",1,0) | X17: 17 | Y17: =IF(W17=0,"",COUNTIFS($T$6:$T$205,T17,$W$6:$W$205,1,$S$6:$S$205,"<"&S17)+COUNTIFS($T$6:$T$205,T17,$W$6:$W$205,1,$S$6:$S$205,S17,$X$6:$X$205,"<"&X17)+1) | Z17: =IF(Y17="","",T17&"_"&Y17) | AA17: =SUBSTITUTE(SUBSTITUTE(SUBSTITUTE(SUBSTITUTE(SUBSTITUTE(INDEX(D17:K17,MIN(8,MAX(1,C17))),"年","/"),"月","/"),"日",""),"-","/"),".","/") | AB17: =IFERROR(MATCH(O17,入力!$C$5:$C$44,0),"") | AC17: =IF(AB17="","",INDEX(入力!$AJ$5:$AJ$44,AB17)) | AD17: =IF(INDEX($D17:$K17,IF(M17=1,2,1))=AC17,1,IF(INDEX($D17:$K17,IF(M17=1,2,1))&INDEX($D17:$K17,IF(M17=1,2,1)+1)=AC17,2,IF(INDEX($D17:$K17,IF(M17=1,2,1))&INDEX($D17:$K17,IF(M17=1,2,1)+1)&INDEX($D17:$K17,IF(M17=1,2,1)+2)=AC17,3,IF(AB17<>"",2,IF(ISNUMBER(MATCH(INDEX($D17:$K17,IF(M17=1,2,1)),入力!$AJ$5:$AJ$44,0)),1,IF(ISNUMBER(MATCH(INDEX($D17:$K17,IF(M17=1,2,1))&INDEX($D17:$K17,IF(M17=1,2,1)+1),入力!$AJ$5:$AJ$44,0)),2,IF(ISNUMBER(MATCH(INDEX($D17:$K17,IF(M17=1,2,1))&INDEX($D17:$K17,IF(M17=1,2,1)+1)&INDEX($D17:$K17,IF(M17=1,2,1)+2),入力!$AJ$5:$AJ$44,0)),3,2)))))))
